Workbook

Sheet Описание
A1: РАСЧЁТЫ К ОТЧЁТУ О НИР
A3: Рабочая книга | B3: Сравнительная оценка электротрактора JINMA YL254ET (ЭТ) и дизельного аналога JINMA JM-254 (Д) по результатам полевых испытаний 15.09–15.10.2026
A4: Назначение | B4: Расчёт единичных показателей обеих машин, нормированных разностей, весов (МАИ + энтропийный метод) и комплексного показателя I для 16 исследованных режимов; пересчёт при изменении исходных данных
A5: Как пользоваться | B5: Изменяйте только ячейки с синим шрифтом на жёлтом фоне на листах «Исходные» и «Веса». Все остальные значения пересчитываются формулами
A6: Ключевые рычаги | B6: S_task (сменное задание; 0 — полная смена), T_year_h (годовая загрузка), c_D и c_el (цены), l_charge_km (удалённость зарядки), P_ch_ac (мощность зарядки), цены машин
A7: Цвета | B7: синий шрифт — исходные данные; чёрный — формулы; зелёный — ссылки на другие листы; жёлтая заливка — изменяемые ячейки
A8: Лист «Исходные» | B8: исходные данные и допущения с источниками и диапазонами вариации (именованные ячейки)
A9: Лист «Проходы» | B9: результаты учётных проходов (значения из журналов CAN 1 Гц и полевых журналов) и расчётные показатели проходов (формулы); буксование — по ГОСТ 7057: δ = 1 − N0/N (N — число оборотов двигателя хода на учётной делянке)
A10: Лист «Опыт_режимы» | B10: средние по повторностям, стандартные отклонения, доверительные интервалы (формулы AVERAGEIFS и т. п.)
A11: Лист «Модели» | B11: коэффициенты моделей: сопротивление передвижению, k = k0 + ε·v² (ЛИНЕЙН), A = A0 + Av·v + Aa·a (ЛИНЕЙН), кривая буксования δ(φ)
A12: Лист «Энергетика» | B12: мощности ЭТ и Д, буксование, запас мощности, допустимость режимов, часовой расход топлива Д (ASAE D497.7)
A13: Лист «Смена» | B13: модель смены: развороты, автономность, подзарядки (до трёх циклов), сменная выработка, энергия, полученная из сети, расход топлива на 1 га
A14: Лист «Экономика» | B14: удельные прямые и совокупные затраты (ГОСТ 34393-2018, ASAE D497.7)
... A19: Проверка | B19: при исходных данных по умолчанию значения комплексного показателя совпадают с отчётом (таблица 5.6, сценарий 1); расхождение собственного вектора МАИ и метода геометрического среднего < 0,001

Sheet Исходные
A1: Обозначение (имя) | B1: Параметр | C1: Значение | D1: Ед. | E1: Статус, источник | F1: Мин. | G1: Макс.
A2: m_ET | B2: Масса ЭТ | C2: 1300 | D2: кг | E2: паспорт изготовителя
A3: m_D | B3: Масса Д | C3: 1140 | D3: кг | E3: TractorData.com
A4: g | B4: Ускорение свободного падения | C4: 9.81 | D4: м/с² | E4: константа
A5: E_bat_kWh | B5: Энергоёмкость батареи | C5: 23.35 | D5: кВт·ч | E5: 304 А·ч × 76,8 В; подтверждено опытом
A6: SOC_max | B6: SOC после зарядки | C6: 98 | D6: % | E6: опыт
A7: SOC_min | B7: Нижняя граница SOC | C7: 30 | D7: % | E7: порог предупреждения BMS (код 61)
A8: P_el_lim | B8: Предельная мощность от батареи | C8: 17.5 | D8: кВт | E8: опыт (17,3–17,5 кВт)
A9: P_mot_1h | B9: Часовая мощность двигателя хода | C9: 12 | D9: кВт | E9: паспорт
A10: P_aux | B10: Собственное потребление систем | C10: 0.18 | D10: кВт | E10: опыт
A11: eta_ep | B11: КПД тягового электропривода | C11: 0.88 | D11: – | E11: допущение | F11: 0.83 | G11: 0.92
A12: eta_tr | B12: КПД трансмиссии | C12: 0.88 | D12: – | E12: допущение | F12: 0.85 | G12: 0.91
A13: P_hyd_idle_D | B13: Потери гидронасоса Д на холостом ходу | C13: 0.15 | D13: кВт | E13: допущение
A14: P_e_nom_D | B14: Номинальная мощность двигателя Д | C14: 18.4 | D14: кВт | E14: паспорт
A15: k_pto_D | B15: Отношение P_ВОМ/P_е для Д | C15: 0.9 | D15: – | E15: допущение | F15: 0.85 | G15: 0.92
A16: k_D | B16: Поправка расхода топлива к ASAE D497.7 | C16: 1 | D16: – | E16: допущение (1,0 — в пользу Д) | F16: 1 | G16: 1.2
A17: sfc_a | B17: ASAE D497.7: коэффициент a | C17: 0.22 | D17: л/(кВт·ч) | E17: ASAE D497.7
A18: sfc_b | B18: ASAE D497.7: коэффициент b | C18: 0.096 | D18: л/(кВт·ч) | E18: ASAE D497.7
A19: LHV_D | B19: Теплота сгорания ДТ | C19: 35.9 | D19: МДж/л | E19: справочное
A20: tank_D | B20: Топливный бак Д | C20: 22 | D20: л | E20: TractorData.com
A21: t_refuel_h | B21: Время дозаправки | C21: 0.15 | D21: ч | E21: допущение
A22: P_ch_ac | B22: Мощность зарядного устройства | C22: 3.5 | D22: кВт | E22: допущение: разъём 16 А, 230 В
A23: eta_ch | B23: КПД зарядного устройства | C23: 0.92 | D23: – | E23: допущение | F23: 0.88 | G23: 0.95
A24: eta_bat | B24: КПД батареи (энергетический) | C24: 0.95 | D24: – | E24: допущение | F24: 0.92 | G24: 0.97
A25: T_shift_h | B25: Продолжительность смены | C25: 8 | D25: ч | E25: принято
A26: tau_svc | B26: Доля смены на работу и переезды | C26: 0.92 | D26: – | E26: допущение
A27: L_run_m | B27: Длина гона | C27: 300 | D27: м | E27: принято
A28: l_charge_km | B28: Удалённость места зарядки | C28: 1 | D28: км | E28: принято
A29: v_transp_kmh | B29: Скорость переезда | C29: 15.4 | D29: км/ч | E29: опыт
A30: P_transp_kW | B30: Мощность при переезде | C30: 6.3 | D30: кВт | E30: опыт
A31: usd_kzt | B31: Курс доллара США | C31: 452.12 | D31: тг | E31: НБРК, 18.10.2026
A32: price_ET_usd | B32: Цена ЭТ (FOB) | C32: 13300 | D32: $ | E32: Made-in-China, Jiangsu Yueda
A33: price_D_usd | B33: Цена Д (FOB) | C33: 5050 | D33: $ | E33: Made-in-China, Jinma
A34: k_landed | B34: Коэффициент «FOB → цена у дилера» | C34: 1.467 | D34: – | E34: 1,10 × 1,16 (НДС) × 1,15 | F34: 1.3 | G34: 1.65
A35: c_el | B35: Цена электроэнергии с НДС | C35: 45.59 | D35: тг/(кВт·ч) | E35: ЭнергоСбыт АЖК с 12.09.2026 | F35: 39.3 | G35: 55
A36: c_D | B36: Цена дизельного топлива | C36: 345 | D36: тг/л | E36: средняя розничная, сент.–окт. 2026 | F36: 300 | G36: 400
A37: wage_month | B37: Средняя зарплата в сельском хозяйстве | C37: 365262 | D37: тг/мес | E37: БНС АСПиР РК, II кв. 2026
A38: h_month | B38: Рабочих часов в месяце | C38: 166 | D38: ч | E38: принято
A39: k_soc | B39: Коэффициент начислений на ФОТ | C39: 1.15 | D39: – | E39: допущение
A40: T_year_h | B40: Годовая загрузка | C40: 600 | D40: ч/год | E40: допущение | F40: 300 | G40: 1000
...

Sheet Проходы
A1: Машина | B1: Сессия | C1: Проход | D1: Блок | E1: Вид | F1: a_пл, м | G1: v_пл, км/ч | H1: Диапазон | I1: n, с | J1: P̄, кВт | K1: s_P, кВт | L1: N, об | M1: v, км/ч | N1: a, м | O1: s_a, м | P1: B, м | Q1: n_ВОМ, мин⁻¹ | R1: W0, га/ч | S1: e, кВт·ч/га | T1: δ | U1: e_V, кДж/м³ | V1: v², м²/с² | W1: F_к, Н | X1: R, Н | Y1: k, кН/м² | Z1: φ | AA1: A, кДж/м³ | AB1: (P−P_aux)/v, кВт·с/м
A2: культиватор | B2: C | C2: 0 | E2: холостой | F2: 0 | G2: 4.5 | H2: L | I2: 80 | J2: 3.1968 | K2: 0.075 | L2: 3288.233 | M2: 4.472 | Q2: 0 | T2: =IF(E2="холостой","",IFERROR(1-AVERAGEIFS($L:$L,$B:$B,B2,$H:$H,H2,$E:$E,"холостой")/L2,"")) | V2: =(M2/3.6)^2 -> 1.543116 | W2: =eta_ep*eta_tr*(J2-P_aux)*1000/(M2/3.6) -> 1880.6699
A3: культиватор | B3: C | C3: 0 | E3: холостой | F3: 0 | G3: 4.5 | H3: L | I3: 80 | J3: 3.1963 | K3: 0.0752 | L3: 3289.433 | M3: 4.489 | Q3: 0 | T3: =IF(E3="холостой","",IFERROR(1-AVERAGEIFS($L:$L,$B:$B,B3,$H:$H,H3,$E:$E,"холостой")/L3,"")) | V3: =(M3/3.6)^2 -> 1.5548704 | W3: =eta_ep*eta_tr*(J3-P_aux)*1000/(M3/3.6) -> 1873.2372
A4: культиватор | B4: C | C4: 0 | E4: холостой | F4: 0 | G4: 4.5 | H4: L | I4: 80 | J4: 3.1981 | K4: 0.075 | L4: 3289.95 | M4: 4.515 | Q4: 0 | T4: =IF(E4="холостой","",IFERROR(1-AVERAGEIFS($L:$L,$B:$B,B4,$H:$H,H4,$E:$E,"холостой")/L4,"")) | V4: =(M4/3.6)^2 -> 1.572934 | W4: =eta_ep*eta_tr*(J4-P_aux)*1000/(M4/3.6) -> 1863.5614
A5: культиватор | B5: C | C5: 0 | E5: холостой | F5: 0 | G5: 4.5 | H5: L | I5: 80 | J5: 3.1988 | K5: 0.073 | L5: 3289.267 | M5: 4.539 | Q5: 0 | T5: =IF(E5="холостой","",IFERROR(1-AVERAGEIFS($L:$L,$B:$B,B5,$H:$H,H5,$E:$E,"холостой")/L5,"")) | V5: =(M5/3.6)^2 -> 1.5897007 | W5: =eta_ep*eta_tr*(J5-P_aux)*1000/(M5/3.6) -> 1854.1378
A6: культиватор | B6: C | C6: 1 | D6: 1 | E6: рабочий | F6: 0.11 | G6: 5.4 | H6: L | I6: 67 | J6: 15.2588 | K6: 0.5465 | L6: 3659.583 | M6: 5.409 | N6: 0.1068 | O6: 0.0047 | P6: 1.204 | Q6: 0 | R6: =IF(P6="","",0.1*P6*M6) -> 0.6512436 | S6: =IF(R6="","",J6/R6) -> 23.430249 | T6: =IF(E6="холостой","",IFERROR(1-AVERAGEIFS($L:$L,$B:$B,B6,$H:$H,H6,$E:$E,"холостой")/L6,"")) -> 0.1012034 | U6: =IF(R6="","",3.6*J6/(P6*N6*M6)) -> 78.978369 | V6: =(M6/3.6)^2 -> 2.2575063 | W6: =eta_ep*eta_tr*(J6-P_aux)*1000*(1-T6)/(M6/3.6) -> 6985.2035 | X6: =W6-f_roll*m_ET*g -> 5117.3019 | Y6: =X6/(P6*N6)/1000 -> 39.796356 | Z6: =X6/(m_ET*g) -> 0.4012626
A7: культиватор | B7: C | C7: 2 | D7: 1 | E7: рабочий | F7: 0.08 | G7: 5.4 | H7: L | I7: 66 | J7: 11.6538 | K7: 0.5561 | L7: 3482.2 | M7: 5.403 | N7: 0.0774 | O7: 0.0047 | P7: 1.208 | Q7: 0 | R7: =IF(P7="","",0.1*P7*M7) -> 0.6526824 | S7: =IF(R7="","",J7/R7) -> 17.855239 | T7: =IF(E7="холостой","",IFERROR(1-AVERAGEIFS($L:$L,$B:$B,B7,$H:$H,H7,$E:$E,"холостой")/L7,"")) -> 0.055418773 | U7: =IF(R7="","",3.6*J7/(P7*N7*M7)) -> 83.047622 | V7: =(M7/3.6)^2 -> 2.2525007 | W7: =eta_ep*eta_tr*(J7-P_aux)*1000*(1-T7)/(M7/3.6) -> 5592.1584 | X7: =W7-f_roll*m_ET*g -> 3724.2568 | Y7: =X7/(P7*N7)/1000 -> 39.831964 | Z7: =X7/(m_ET*g) -> 0.29202986
A8: культиватор | B8: C | C8: 3 | D8: 1 | E8: рабочий | F8: 0.14 | G8: 4.5 | H8: L | I8: 80 | J8: 15.7265 | K8: 0.4797 | L8: 3814.133 | M8: 4.452 | N8: 0.1388 | O8: 0.0052 | P8: 1.19 | Q8: 0 | R8: =IF(P8="","",0.1*P8*M8) -> 0.529788 | S8: =IF(R8="","",J8/R8) -> 29.684515 | T8: =IF(E8="холостой","",IFERROR(1-AVERAGEIFS($L:$L,$B:$B,B8,$H:$H,H8,$E:$E,"холостой")/L8,"")) -> 0.13762295 | U8: =IF(R8="","",3.6*J8/(P8*N8*M8)) -> 76.991538 | V8: =(M8/3.6)^2 -> 1.5293444 | W8: =eta_ep*eta_tr*(J8-P_aux)*1000*(1-T8)/(M8/3.6) -> 8395.4216 | X8: =W8-f_roll*m_ET*g -> 6527.52 | Y8: =X8/(P8*N8)/1000 -> 39.519531 | Z8: =X8/(m_ET*g) -> 0.51184192
A9: культиватор | B9: C | C9: 4 | D9: 1 | E9: рабочий | F9: 0.11 | G9: 4.5 | H9: L | I9: 79 | J9: 11.9966 | K9: 0.582 | L9: 3590.317 | M9: 4.547 | N9: 0.1076 | O9: 0.006 | P9: 1.185 | Q9: 0 | R9: =IF(P9="","",0.1*P9*M9) -> 0.5388195 | S9: =IF(R9="","",J9/R9) -> 22.264599 | T9: =IF(E9="холостой","",IFERROR(1-AVERAGEIFS($L:$L,$B:$B,B9,$H:$H,H9,$E:$E,"холостой")/L9,"")) -> 0.083863417 | U9: =IF(R9="","",3.6*J9/(P9*N9*M9)) -> 74.491223 | V9: =(M9/3.6)^2 -> 1.5953093 | W9: =eta_ep*eta_tr*(J9-P_aux)*1000*(1-T9)/(M9/3.6) -> 6637.3642 | X9: =W9-f_roll*m_ET*g -> 4769.4627 | Y9: =X9/(P9*N9)/1000 -> 37.40579 | Z9: =X9/(m_ET*g) -> 0.37398751
A10: культиватор | B10: C | C10: 5 | D10: 1 | E10: рабочий | F10: 0.11 | G10: 3.6 | H10: L | I10: 100 | J10: 10.0252 | K10: 0.375 | L10: 3622.767 | M10: 3.572 | N10: 0.1121 | O10: 0.0048 | P10: 1.207 | Q10: 0 | R10: =IF(P10="","",0.1*P10*M10) -> 0.4311404 | S10: =IF(R10="","",J10/R10) -> 23.25275 | T10: =IF(E10="холостой","",IFERROR(1-AVERAGEIFS($L:$L,$B:$B,B10,$H:$H,H10,$E:$E,"холостой")/L10,"")) -> 0.092069473 | U10: =IF(R10="","",3.6*J10/(P10*N10*M10)) -> 74.674309 | V10: =(M10/3.6)^2 -> 0.98450494 | W10: =eta_ep*eta_tr*(J10-P_aux)*1000*(1-T10)/(M10/3.6) -> 6976.4351 | X10: =W10-f_roll*m_ET*g -> 5108.5335 | Y10: =X10/(P10*N10)/1000 -> 37.755773 | Z10: =X10/(m_ET*g) -> 0.40057504
A11: культиватор | B11: C | C11: 6 | D11: 1 | E11: рабочий | F11: 0.08 | G11: 4.5 | H11: L | I11: 80 | J11: 9.1676 | K11: 0.3946 | L11: 3509.4 | M11: 4.564 | N11: 0.0794 | O11: 0.006 | P11: 1.191 | Q11: 0 | R11: =IF(P11="","",0.1*P11*M11) -> 0.5435724 | S11: =IF(R11="","",J11/R11) -> 16.865463 | T11: =IF(E11="холостой","",IFERROR(1-AVERAGEIFS($L:$L,$B:$B,B11,$H:$H,H11,$E:$E,"холостой")/L11,"")) -> 0.062739856 | U11: =IF(R11="","",3.6*J11/(P11*N11*M11)) -> 76.468093 | V11: =(M11/3.6)^2 -> 1.6072605 | W11: =eta_ep*eta_tr*(J11-P_aux)*1000*(1-T11)/(M11/3.6) -> 5145.4824 | X11: =W11-f_roll*m_ET*g -> 3277.5808 | Y11: =X11/(P11*N11)/1000 -> 34.659408 | Z11: =X11/(m_ET*g) -> 0.25700469
A12: культиватор | B12: C | C12: 7 | D12: 1 | E12: рабочий | F12: 0.08 | G12: 3.6 | H12: L | I12: 100 | J12: 7.483 | K12: 0.2448 | L12: 3501.467 | M12: 3.63 | N12: 0.0772 | O12: 0.0049 | P12: 1.205 | Q12: 0 | R12: =IF(P12="","",0.1*P12*M12) -> 0.437415 | S12: =IF(R12="","",J12/R12) -> 17.107324 | T12: =IF(E12="холостой","",IFERROR(1-AVERAGEIFS($L:$L,$B:$B,B12,$H:$H,H12,$E:$E,"холостой")/L12,"")) -> 0.060616379 | U12: =IF(R12="","",3.6*J12/(P12*N12*M12)) -> 79.775085 | V12: =(M12/3.6)^2 -> 1.0167361 | W12: =eta_ep*eta_tr*(J12-P_aux)*1000*(1-T12)/(M12/3.6) -> 5268.7247 | X12: =W12-f_roll*m_ET*g -> 3400.8231 | Y12: =X12/(P12*N12)/1000 -> 36.55777 | Z12: =X12/(m_ET*g) -> 0.26666848
A13: культиватор | B13: C | C13: 8 | D13: 1 | E13: рабочий | F13: 0.14 | G13: 3.6 | H13: L | I13: 100 | J13: 11.9499 | K13: 0.4091 | L13: 3791.433 | M13: 3.581 | N13: 0.1382 | O13: 0.0052 | P13: 1.187 | Q13: 0 | R13: =IF(P13="","",0.1*P13*M13) -> 0.4250647 | S13: =IF(R13="","",J13/R13) -> 28.113132 | T13: =IF(E13="холостой","",IFERROR(1-AVERAGEIFS($L:$L,$B:$B,B13,$H:$H,H13,$E:$E,"холостой")/L13,"")) -> 0.13245975 | U13: =IF(R13="","",3.6*J13/(P13*N13*M13)) -> 73.232471 | V13: =(M13/3.6)^2 -> 0.9894723 | W13: =eta_ep*eta_tr*(J13-P_aux)*1000*(1-T13)/(M13/3.6) -> 7949.2459 | X13: =W13-f_roll*m_ET*g -> 6081.3443 | Y13: =X13/(P13*N13)/1000 -> 37.071558 | Z13: =X13/(m_ET*g) -> 0.47685598
A14: культиватор | B14: C | C14: 9 | D14: 2 | E14: рабочий | F14: 0.08 | G14: 5.4 | H14: L | I14: 67 | J14: 12.0397 | K14: 0.3817 | L14: 3534.25 | M14: 5.407 | N14: 0.0807 | O14: 0.0053 | P14: 1.195 | Q14: 0 | R14: =IF(P14="","",0.1*P14*M14) -> 0.6461365 | S14: =IF(R14="","",J14/R14) -> 18.633369 | T14: =IF(E14="холостой","",IFERROR(1-AVERAGEIFS($L:$L,$B:$B,B14,$H:$H,H14,$E:$E,"холостой")/L14,"")) -> 0.069329914 | U14: =IF(R14="","",3.6*J14/(P14*N14*M14)) -> 83.122837 | V14: =(M14/3.6)^2 -> 2.2558371 | W14: =eta_ep*eta_tr*(J14-P_aux)*1000*(1-T14)/(M14/3.6) -> 5690.8997 | X14: =W14-f_roll*m_ET*g -> 3822.9982 | Y14: =X14/(P14*N14)/1000 -> 39.642647 | Z14: =X14/(m_ET*g) -> 0.29977246
A15: культиватор | B15: C | C15: 10 | D15: 2 | E15: рабочий | F15: 0.08 | G15: 4.5 | H15: L | I15: 80 | J15: 9.4895 | K15: 0.4175 | L15: 3509.967 | M15: 4.511 | N15: 0.0789 | O15: 0.0053 | P15: 1.198 | Q15: 0 | R15: =IF(P15="","",0.1*P15*M15) -> 0.5404178 | S15: =IF(R15="","",J15/R15) -> 17.559562 | T15: =IF(E15="холостой","",IFERROR(1-AVERAGEIFS($L:$L,$B:$B,B15,$H:$H,H15,$E:$E,"холостой")/L15,"")) -> 0.062891261 | U15: =IF(R15="","",3.6*J15/(P15*N15*M15)) -> 80.119676 | V15: =(M15/3.6)^2 -> 1.5701482 | W15: =eta_ep*eta_tr*(J15-P_aux)*1000*(1-T15)/(M15/3.6) -> 5391.5218 | X15: =W15-f_roll*m_ET*g -> 3523.6202 | Y15: =X15/(P15*N15)/1000 -> 37.278229 | Z15: =X15/(m_ET*g) -> 0.27629736
A16: культиватор | B16: C | C16: 11 | D16: 2 | E16: рабочий | F16: 0.08 | G16: 3.6 | H16: L | I16: 100 | J16: 7.6455 | K16: 0.2684 | L16: 3502.617 | M16: 3.591 | N16: 0.081 | O16: 0.0049 | P16: 1.197 | Q16: 0 | R16: =IF(P16="","",0.1*P16*M16) -> 0.4298427 | S16: =IF(R16="","",J16/R16) -> 17.786739 | T16: =IF(E16="холостой","",IFERROR(1-AVERAGEIFS($L:$L,$B:$B,B16,$H:$H,H16,$E:$E,"холостой")/L16,"")) -> 0.060924803 | U16: =IF(R16="","",3.6*J16/(P16*N16*M16)) -> 79.052174 | V16: =(M16/3.6)^2 -> 0.99500625 | W16: =eta_ep*eta_tr*(J16-P_aux)*1000*(1-T16)/(M16/3.6) -> 5442.6663 | X16: =W16-f_roll*m_ET*g -> 3574.7648 | Y16: =X16/(P16*N16)/1000 -> 36.869589 | Z16: =X16/(m_ET*g) -> 0.28030775
A17: культиватор | B17: C | C17: 12 | D17: 2 | E17: рабочий | F17: 0.14 | G17: 3.6 | H17: L | I17: 100 | J17: 12.2488 | K17: 0.4212 | L17: 3790.533 | M17: 3.581 | N17: 0.1414 | O17: 0.0046 | P17: 1.205 | Q17: 0 | R17: =IF(P17="","",0.1*P17*M17) -> 0.4315105 | S17: =IF(R17="","",J17/R17) -> 28.385868 | T17: =IF(E17="холостой","",IFERROR(1-AVERAGEIFS($L:$L,$B:$B,B17,$H:$H,H17,$E:$E,"холостой")/L17,"")) -> 0.13225376 | U17: =IF(R17="","",3.6*J17/(P17*N17*M17)) -> 72.269536 | V17: =(M17/3.6)^2 -> 0.9894723 | W17: =eta_ep*eta_tr*(J17-P_aux)*1000*(1-T17)/(M17/3.6) -> 8153.0547 | X17: =W17-f_roll*m_ET*g -> 6285.1531 | Y17: =X17/(P17*N17)/1000 -> 36.887515 | Z17: =X17/(m_ET*g) -> 0.49283722
... A29: культиватор | B29: C | C29: 24 | D29: 3 | E29: рабочий | F29: 0.08 | G29: 5.4 | H29: L | I29: 66 | J29: 11.5041 | K29: 0.4169 | L29: 3481.983 | M29: 5.435 | N29: 0.0788 | O29: 0.0057 | P29: 1.206 | Q29: 0 | R29: =IF(P29="","",0.1*P29*M29) -> 0.655461 | S29: =IF(R29="","",J29/R29) -> 17.551159 | T29: =IF(E29="холостой","",IFERROR(1-AVERAGEIFS($L:$L,$B:$B,B29,$H:$H,H29,$E:$E,"холостой")/L29,"")) -> 0.055359906 | U29: =IF(R29="","",3.6*J29/(P29*N29*M29)) -> 80.182958 | V29: =(M29/3.6)^2 -> 2.2792612 | W29: =eta_ep*eta_tr*(J29-P_aux)*1000*(1-T29)/(M29/3.6) -> 5487.043 | X29: =W29-f_roll*m_ET*g -> 3619.1415 | Y29: =X29/(P29*N29)/1000 -> 38.083077 | Z29: =X29/(m_ET*g) -> 0.28378746
A30: фреза | B30: T1 | C30: 0 | E30: холостой | F30: 0 | G30: 2.7 | H30: П2 | I30: 133 | J30: 1.7092 | K30: 0.0564 | L30: 8444.817 | M30: 2.694 | Q30: 0 | T30: =IF(E30="холостой","",IFERROR(1-AVERAGEIFS($L:$L,$B:$B,B30,$H:$H,H30,$E:$E,"холостой")/L30,"")) | V30: =(M30/3.6)^2 -> 0.56000278 | AB30: =(J30-P_aux)/(M30/3.6) -> 2.0434744
A31: фреза | B31: T1 | C31: 0 | E31: холостой | F31: 0 | G31: 2.7 | H31: П2 | I31: 133 | J31: 1.7095 | K31: 0.0576 | L31: 8445.033 | M31: 2.7 | Q31: 0 | T31: =IF(E31="холостой","",IFERROR(1-AVERAGEIFS($L:$L,$B:$B,B31,$H:$H,H31,$E:$E,"холостой")/L31,"")) | V31: =(M31/3.6)^2 -> 0.5625 | AB31: =(J31-P_aux)/(M31/3.6) -> 2.0393333
A32: фреза | B32: T1 | C32: 0 | E32: холостой | F32: 0 | G32: 2.7 | H32: П2 | I32: 133 | J32: 1.7086 | K32: 0.0581 | L32: 8445.283 | M32: 2.709 | Q32: 0 | T32: =IF(E32="холостой","",IFERROR(1-AVERAGEIFS($L:$L,$B:$B,B32,$H:$H,H32,$E:$E,"холостой")/L32,"")) | V32: =(M32/3.6)^2 -> 0.56625625 | AB32: =(J32-P_aux)/(M32/3.6) -> 2.0313621
A33: фреза | B33: T1 | C33: 0 | E33: холостой | F33: 0 | G33: 2.7 | H33: П2 | I33: 133 | J33: 1.7092 | K33: 0.057 | L33: 8445.683 | M33: 2.701 | Q33: 0 | T33: =IF(E33="холостой","",IFERROR(1-AVERAGEIFS($L:$L,$B:$B,B33,$H:$H,H33,$E:$E,"холостой")/L33,"")) | V33: =(M33/3.6)^2 -> 0.56291674 | AB33: =(J33-P_aux)/(M33/3.6) -> 2.0381785
A34: фреза | B34: T2 | C34: 0 | E34: холостой | F34: 0 | G34: 2.7 | H34: П2 | I34: 133 | J34: 1.7389 | K34: 0.038 | L34: 8445.233 | M34: 2.693 | Q34: 0 | T34: =IF(E34="холостой","",IFERROR(1-AVERAGEIFS($L:$L,$B:$B,B34,$H:$H,H34,$E:$E,"холостой")/L34,"")) | V34: =(M34/3.6)^2 -> 0.55958711 | AB34: =(J34-P_aux)/(M34/3.6) -> 2.0839361
A35: фреза | B35: T2 | C35: 0 | E35: холостой | F35: 0 | G35: 2.7 | H35: П2 | I35: 133 | J35: 1.7414 | K35: 0.039 | L35: 8443.667 | M35: 2.711 | Q35: 0 | T35: =IF(E35="холостой","",IFERROR(1-AVERAGEIFS($L:$L,$B:$B,B35,$H:$H,H35,$E:$E,"холостой")/L35,"")) | V35: =(M35/3.6)^2 -> 0.56709267 | AB35: =(J35-P_aux)/(M35/3.6) -> 2.0734194
A36: фреза | B36: T2 | C36: 0 | E36: холостой | F36: 0 | G36: 2.7 | H36: П2 | I36: 133 | J36: 1.7388 | K36: 0.039 | L36: 8444.867 | M36: 2.695 | Q36: 0 | T36: =IF(E36="холостой","",IFERROR(1-AVERAGEIFS($L:$L,$B:$B,B36,$H:$H,H36,$E:$E,"холостой")/L36,"")) | V36: =(M36/3.6)^2 -> 0.5604186 | AB36: =(J36-P_aux)/(M36/3.6) -> 2.082256
A37: фреза | B37: T2 | C37: 0 | E37: холостой | F37: 0 | G37: 2.7 | H37: П2 | I37: 133 | J37: 1.738 | K37: 0.039 | L37: 8444.533 | M37: 2.699 | Q37: 0 | T37: =IF(E37="холостой","",IFERROR(1-AVERAGEIFS($L:$L,$B:$B,B37,$H:$H,H37,$E:$E,"холостой")/L37,"")) | V37: =(M37/3.6)^2 -> 0.56208341 | AB37: =(J37-P_aux)/(M37/3.6) -> 2.078103
A38: фреза | B38: T1 | C38: 1 | D38: 1 | E38: рабочий | F38: 0.12 | G38: 2.7 | H38: П2 | I38: 134 | J38: 12.9278 | K38: 0.2612 | L38: 8480.05 | M38: 2.697 | N38: 0.1197 | O38: 0.005 | P38: 1.232 | Q38: 540 | R38: =IF(P38="","",0.1*P38*M38) -> 0.3322704 | S38: =IF(R38="","",J38/R38) -> 38.907468 | T38: =IF(E38="холостой","",IFERROR(1-AVERAGEIFS($L:$L,$B:$B,B38,$H:$H,H38,$E:$E,"холостой")/L38,"")) -> 0.0041091739 | U38: =IF(R38="","",3.6*J38/(P38*N38*M38)) -> 117.01494 | V38: =(M38/3.6)^2 -> 0.56125069 | AA38: =(J38-P_aux-c_move*M38/3.6-P_rot0)/(P38*N38*M38/3.6) -> 92.543951
A39: фреза | B39: T1 | C39: 2 | D39: 1 | E39: рабочий | F39: 0.08 | G39: 2.7 | H39: П2 | I39: 134 | J39: 10.0222 | K39: 0.2657 | L39: 8479.65 | M39: 2.689 | N39: 0.0833 | O39: 0.0041 | P39: 1.255 | Q39: 539.97 | R39: =IF(P39="","",0.1*P39*M39) -> 0.3374695 | S39: =IF(R39="","",J39/R39) -> 29.698091 | T39: =IF(E39="холостой","",IFERROR(1-AVERAGEIFS($L:$L,$B:$B,B39,$H:$H,H39,$E:$E,"холостой")/L39,"")) -> 0.004062196 | U39: =IF(R39="","",3.6*J39/(P39*N39*M39)) -> 128.34709 | V39: =(M39/3.6)^2 -> 0.557926 | AA39: =(J39-P_aux-c_move*M39/3.6-P_rot0)/(P39*N39*M39/3.6) -> 93.78323
A40: фреза | B40: T1 | C40: 3 | D40: 1 | E40: рабочий | F40: 0.16 | G40: 1.8 | H40: П1 | I40: 200 | J40: 12.6134 | K40: 0.2903 | L40: 12655.533 | M40: 1.797 | N40: 0.1603 | O40: 0.0047 | P40: 1.245 | Q40: 539.93 | R40: =IF(P40="","",0.1*P40*M40) -> 0.2237265 | S40: =IF(R40="","",J40/R40) -> 56.378659 | T40: =IF(E40="холостой","",IFERROR(1-AVERAGEIFS($L:$L,$B:$B,B40,$H:$H,H40,$E:$E,"холостой")/L40,"")) | U40: =IF(R40="","",3.6*J40/(P40*N40*M40)) -> 126.61458 | V40: =(M40/3.6)^2 -> 0.24916736 | AA40: =(J40-P_aux-c_move*M40/3.6-P_rot0)/(P40*N40*M40/3.6) -> 104.64255
A41: фреза | B41: T1 | C41: 4 | D41: 1 | E41: рабочий | F41: 0.08 | G41: 3.6 | H41: П3 | I41: 100 | J41: 11.8202 | K41: 0.2779 | L41: 6327.833 | M41: 3.577 | N41: 0.0821 | O41: 0.0047 | P41: 1.253 | Q41: 539.99 | R41: =IF(P41="","",0.1*P41*M41) -> 0.4481981 | S41: =IF(R41="","",J41/R41) -> 26.372713 | T41: =IF(E41="холостой","",IFERROR(1-AVERAGEIFS($L:$L,$B:$B,B41,$H:$H,H41,$E:$E,"холостой")/L41,"")) | U41: =IF(R41="","",3.6*J41/(P41*N41*M41)) -> 115.64162 | V41: =(M41/3.6)^2 -> 0.98726304 | AA41: =(J41-P_aux-c_move*M41/3.6-P_rot0)/(P41*N41*M41/3.6) -> 84.268199
A42: фреза | B42: T1 | C42: 5 | D42: 1 | E42: рабочий | F42: 0.12 | G42: 1.8 | H42: П1 | I42: 201 | J42: 9.9765 | K42: 0.2525 | L42: 12720.317 | M42: 1.791 | N42: 0.119 | O42: 0.0036 | P42: 1.247 | Q42: 539.97 | R42: =IF(P42="","",0.1*P42*M42) -> 0.2233377 | S42: =IF(R42="","",J42/R42) -> 44.670022 | T42: =IF(E42="холостой","",IFERROR(1-AVERAGEIFS($L:$L,$B:$B,B42,$H:$H,H42,$E:$E,"холостой")/L42,"")) | U42: =IF(R42="","",3.6*J42/(P42*N42*M42)) -> 135.1362 | V42: =(M42/3.6)^2 -> 0.24750625 | AA42: =(J42-P_aux-c_move*M42/3.6-P_rot0)/(P42*N42*M42/3.6) -> 105.53354
A43: фреза | B43: T1 | C43: 6 | D43: 1 | E43: рабочий | F43: 0.08 | G43: 1.8 | H43: П1 | I43: 201 | J43: 7.1492 | K43: 0.1728 | L43: 12719.533 | M43: 1.788 | N43: 0.0768 | O43: 0.0035 | P43: 1.266 | Q43: 539.98 | R43: =IF(P43="","",0.1*P43*M43) -> 0.2263608 | S43: =IF(R43="","",J43/R43) -> 31.583207 | T43: =IF(E43="холостой","",IFERROR(1-AVERAGEIFS($L:$L,$B:$B,B43,$H:$H,H43,$E:$E,"холостой")/L43,"")) | U43: =IF(R43="","",3.6*J43/(P43*N43*M43)) -> 148.04628 | V43: =(M43/3.6)^2 -> 0.24667778 | AA43: =(J43-P_aux-c_move*M43/3.6-P_rot0)/(P43*N43*M43/3.6) -> 102.82569
A44: фреза | B44: T1 | C44: 7 | D44: 1 | E44: рабочий | F44: 0.12 | G44: 3.6 | H44: П3 | I44: 100 | J44: 16.6278 | K44: 0.6554 | L44: 6270.867 | M44: 3.578 | N44: 0.122 | O44: 0.0045 | P44: 1.251 | Q44: 535.1 | R44: =IF(P44="","",0.1*P44*M44) -> 0.4476078 | S44: =IF(R44="","",J44/R44) -> 37.148146 | T44: =IF(E44="холостой","",IFERROR(1-AVERAGEIFS($L:$L,$B:$B,B44,$H:$H,H44,$E:$E,"холостой")/L44,"")) | U44: =IF(R44="","",3.6*J44/(P44*N44*M44)) -> 109.61748 | V44: =(M44/3.6)^2 -> 0.98781512 | AA44: =(J44-P_aux-c_move*M44/3.6-P_rot0)/(P44*N44*M44/3.6) -> 88.4731
A45: фреза | B45: T1 | C45: 8 | D45: 1 | E45: рабочий | F45: 0.16 | G45: 2.7 | H45: П2 | I45: 134 | J45: 16.2409 | K45: 0.5248 | L45: 8421.917 | M45: 2.681 | N45: 0.1581 | O45: 0.0022 | P45: 1.24 | Q45: 536.27 | R45: =IF(P45="","",0.1*P45*M45) -> 0.332444 | S45: =IF(R45="","",J45/R45) -> 48.85304 | T45: =IF(E45="холостой","",IFERROR(1-AVERAGEIFS($L:$L,$B:$B,B45,$H:$H,H45,$E:$E,"холостой")/L45,"")) -> -0.0027650474 | U45: =IF(R45="","",3.6*J45/(P45*N45*M45)) -> 111.24032 | V45: =(M45/3.6)^2 -> 0.55461119 | AA45: =(J45-P_aux-c_move*M45/3.6-P_rot0)/(P45*N45*M45/3.6) -> 92.785293
A46: фреза | B46: T1 | C46: 9 | D46: 2 | E46: рабочий | F46: 0.12 | G46: 1.8 | H46: П1 | I46: 201 | J46: 9.9434 | K46: 0.2385 | L46: 12720.283 | M46: 1.787 | N46: 0.1186 | O46: 0.0043 | P46: 1.249 | Q46: 540 | R46: =IF(P46="","",0.1*P46*M46) -> 0.2231963 | S46: =IF(R46="","",J46/R46) -> 44.550022 | T46: =IF(E46="холостой","",IFERROR(1-AVERAGEIFS($L:$L,$B:$B,B46,$H:$H,H46,$E:$E,"холостой")/L46,"")) | U46: =IF(R46="","",3.6*J46/(P46*N46*M46)) -> 135.22772 | V46: =(M46/3.6)^2 -> 0.24640193 | AA46: =(J46-P_aux-c_move*M46/3.6-P_rot0)/(P46*N46*M46/3.6) -> 105.53751
A47: фреза | B47: T1 | C47: 10 | D47: 2 | E47: рабочий | F47: 0.08 | G47: 3.6 | H47: П3 | I47: 100 | J47: 12.2048 | K47: 0.3449 | L47: 6328.85 | M47: 3.593 | N47: 0.0825 | O47: 0.0045 | P47: 1.246 | Q47: 540.05 | R47: =IF(P47="","",0.1*P47*M47) -> 0.4476878 | S47: =IF(R47="","",J47/R47) -> 27.261855 | T47: =IF(E47="холостой","",IFERROR(1-AVERAGEIFS($L:$L,$B:$B,B47,$H:$H,H47,$E:$E,"холостой")/L47,"")) | U47: =IF(R47="","",3.6*J47/(P47*N47*M47)) -> 118.96082 | V47: =(M47/3.6)^2 -> 0.99611489 | AA47: =(J47-P_aux-c_move*M47/3.6-P_rot0)/(P47*N47*M47/3.6) -> 87.614744
A48: фреза | B48: T1 | C48: 11 | D48: 2 | E48: рабочий | F48: 0.08 | G48: 1.8 | H48: П1 | I48: 201 | J48: 7.3719 | K48: 0.2891 | L48: 12721.383 | M48: 1.789 | N48: 0.0785 | O48: 0.0041 | P48: 1.218 | Q48: 540.06 | R48: =IF(P48="","",0.1*P48*M48) -> 0.2179002 | S48: =IF(R48="","",J48/R48) -> 33.831543 | T48: =IF(E48="холостой","",IFERROR(1-AVERAGEIFS($L:$L,$B:$B,B48,$H:$H,H48,$E:$E,"холостой")/L48,"")) | U48: =IF(R48="","",3.6*J48/(P48*N48*M48)) -> 155.15103 | V48: =(M48/3.6)^2 -> 0.24695378 | AA48: =(J48-P_aux-c_move*M48/3.6-P_rot0)/(P48*N48*M48/3.6) -> 109.1799
A49: фреза | B49: T1 | C49: 12 | D49: 2 | E49: рабочий | F49: 0.16 | G49: 2.7 | H49: П2 | I49: 133 | J49: 16.3447 | K49: 0.5072 | L49: 8388.6 | M49: 2.689 | N49: 0.159 | O49: 0.0047 | P49: 1.264 | Q49: 538.23 | R49: =IF(P49="","",0.1*P49*M49) -> 0.3398896 | S49: =IF(R49="","",J49/R49) -> 48.088262 | T49: =IF(E49="холостой","",IFERROR(1-AVERAGEIFS($L:$L,$B:$B,B49,$H:$H,H49,$E:$E,"холостой")/L49,"")) -> -0.0067477291 | U49: =IF(R49="","",3.6*J49/(P49*N49*M49)) -> 108.87908 | V49: =(M49/3.6)^2 -> 0.557926 | AA49: =(J49-P_aux-c_move*M49/3.6-P_rot0)/(P49*N49*M49/3.6) -> 90.90003
... A61: фреза | B61: T2 | C61: 25 | D61: 3 | E61: рабочий | F61: 0.12 | G61: 1.8 | H61: П1 | I61: 201 | J61: 9.8814 | K61: 0.3387 | L61: 12720.933 | M61: 1.794 | N61: 0.1196 | O61: 0.0043 | P61: 1.254 | Q61: 540.01 | R61: =IF(P61="","",0.1*P61*M61) -> 0.2249676 | S61: =IF(R61="","",J61/R61) -> 43.923658 | T61: =IF(E61="холостой","",IFERROR(1-AVERAGEIFS($L:$L,$B:$B,B61,$H:$H,H61,$E:$E,"холостой")/L61,"")) | U61: =IF(R61="","",3.6*J61/(P61*N61*M61)) -> 132.21168 | V61: =(M61/3.6)^2 -> 0.24833611 | AA61: =(J61-P_aux-c_move*M61/3.6-P_rot0)/(P61*N61*M61/3.6) -> 102.94797

Sheet Модели
A1: Имя | B1: Коэффициент | C1: Значение | D1: Ед. | E1: Формула / способ определения
A2: f_roll | B2: Коэффициент сопротивления передвижению | C2: =AVERAGE(Проходы!W2:W5)/(m_ET*g) -> 0.14646762 | D2: – | E2: по холостым проходам с культиватором (F_к/G)
A3: k_0 | B3: k0 – удельное сопротивление при v → 0 | C3: =INDEX(LINEST(Проходы!Y6:Y29,Проходы!V6:V29),1,2)*1000 -> 34579.423 | D3: Н/м² | E3: ЛИНЕЙН(k; v²)
A4: eps | B4: ε – скоростной коэффициент | C4: =INDEX(LINEST(Проходы!Y6:Y29,Проходы!V6:V29),1,1)*1000 -> 1989.1759 | D4: Н·с²/м⁴ | E4: ЛИНЕЙН(k; v²)
A5: R2_k | B5: R² модели k | C5: =INDEX(LINEST(Проходы!Y6:Y29,Проходы!V6:V29,TRUE(),TRUE()),3,1) -> 0.41971559 | D5: – | E5: ЛИНЕЙН, статистика
A6: phi_max | B6: φ_max кривой буксования | C6: 0.821404 | D6: – | E6: нелинейный МНК (Python, scipy.curve_fit); значение
A7: k_slip | B7: k_δ кривой буксования | C7: 6.745697 | D7: – | E7: нелинейный МНК (Python); значение
A8: c_move | B8: Удельная мощность передвижения с фрезой | C8: =AVERAGE(Проходы!AB30:AB37) -> 2.0587579 | D8: кВт·с/м | E8: (P − P_aux)/v по холостым проходам с фрезой на П2
A9: P_rot0 | B9: Мощность холостого вращения ротора сверх P_aux | C9: 0.9812 | D9: кВт | E9: опыт: холостое вращение ротора, ВОМ 540
A10: A_0 | B10: A0 | C10: =INDEX(LINEST(Проходы!AA38:AA61,Проходы!M38:N61),1,3) -> 125.55065 | D10: кДж/м³ | E10: ЛИНЕЙН(A; v, a)
A11: A_v | B11: Av | C11: =INDEX(LINEST(Проходы!AA38:AA61,Проходы!M38:N61),1,2) -> -10.273753 | D11: кДж/(м³·км/ч) | E11: ЛИНЕЙН(A; v, a)
A12: A_a | B12: Aa | C12: =INDEX(LINEST(Проходы!AA38:AA61,Проходы!M38:N61),1,1) -> -28.225668 | D12: кДж/(м³·м) | E12: ЛИНЕЙН(A; v, a)
A13: slip_till_meas | B13: Буксование с фрезой (среднее по проходам на П2) | C13: =AVERAGE(Проходы!T38:T61) -> 0.001754916 | D13: – | E13: справочно; δ = 1 − N0/N
A14: slip_till | B14: Буксование с фрезой, принятое в расчёте | C14: 0 | D14: – | E14: принято 0 (измеренное значение пренебрежимо мало)
A15: cv_P | B15: Коэффициент вариации мощности (медиана) | C15: 0.032418 | D15: – | E15: медиана s_P/P̄ по рабочим проходам
A16: turn_t | B16: Продолжительность разворота | C16: 32.194 | D16: с | E16: опыт
A17: turn_P | B17: Мощность на развороте | C17: 2.9974 | D17: кВт | E17: опыт

Sheet Опыт_режимы
A1: Машина | B1: a, м | C1: v, км/ч | D1: n | E1: P̄, кВт | F1: s_P | G1: Δ0,95 P | H1: e, кВт·ч/га | I1: s_e | J1: Δ0,95 e | K1: δ | L1: W0, га/ч
A2: культиватор | B2: 0.08 | C2: 3.6 | D2: =COUNTIFS(Проходы!$A$6:$A$61,$A2,Проходы!$F$6:$F$61,$B2,Проходы!$G$6:$G$61,$C2,Проходы!$E$6:$E$61,"рабочий") -> 3 | E2: =AVERAGEIFS(Проходы!$J$6:$J$61,Проходы!$A$6:$A$61,$A2,Проходы!$F$6:$F$61,$B2,Проходы!$G$6:$G$61,$C2,Проходы!$E$6:$E$61,"рабочий") -> 7.4258 | F2: =SQRT(SUMPRODUCT((Проходы!$A$6:$A$61=$A2)*(Проходы!$F$6:$F$61=$B2)*(Проходы!$G$6:$G$61=$C2)*(Проходы!$E$6:$E$61="рабочий")*(Проходы!$J$6:$J$61-E2)^2)/(D2-1)) -> 0.25319315 | G2: =TINV(0.05,D2-1)*F2/SQRT(D2) -> 0.62896665 | H2: =AVERAGEIFS(Проходы!$S$6:$S$61,Проходы!$A$6:$A$61,$A2,Проходы!$F$6:$F$61,$B2,Проходы!$G$6:$G$61,$C2,Проходы!$E$6:$E$61,"рабочий") -> 17.135508 | I2: =SQRT(SUMPRODUCT((Проходы!$A$6:$A$61=$A2)*(Проходы!$F$6:$F$61=$B2)*(Проходы!$G$6:$G$61=$C2)*(Проходы!$E$6:$E$61="рабочий")*(Проходы!$S$6:$S$61-H2)^2)/(D2-1)) -> 0.63760636 | J2: =TINV(0.05,D2-1)*I2/SQRT(D2) -> 1.583902 | K2: =IFERROR(AVERAGEIFS(Проходы!$T$6:$T$61,Проходы!$A$6:$A$61,$A2,Проходы!$F$6:$F$61,$B2,Проходы!$G$6:$G$61,$C2,Проходы!$E$6:$E$61,"рабочий"),"–") -> 0.060768364 | L2: =AVERAGEIFS(Проходы!$R$6:$R$61,Проходы!$A$6:$A$61,$A2,Проходы!$F$6:$F$61,$B2,Проходы!$G$6:$G$61,$C2,Проходы!$E$6:$E$61,"рабочий") -> 0.43339913
A3: культиватор | B3: 0.08 | C3: 4.5 | D3: =COUNTIFS(Проходы!$A$6:$A$61,$A3,Проходы!$F$6:$F$61,$B3,Проходы!$G$6:$G$61,$C3,Проходы!$E$6:$E$61,"рабочий") -> 3 | E3: =AVERAGEIFS(Проходы!$J$6:$J$61,Проходы!$A$6:$A$61,$A3,Проходы!$F$6:$F$61,$B3,Проходы!$G$6:$G$61,$C3,Проходы!$E$6:$E$61,"рабочий") -> 9.3814333 | F3: =SQRT(SUMPRODUCT((Проходы!$A$6:$A$61=$A3)*(Проходы!$F$6:$F$61=$B3)*(Проходы!$G$6:$G$61=$C3)*(Проходы!$E$6:$E$61="рабочий")*(Проходы!$J$6:$J$61-E3)^2)/(D3-1)) -> 0.18518867 | G3: =TINV(0.05,D3-1)*F3/SQRT(D3) -> 0.46003416 | H3: =AVERAGEIFS(Проходы!$S$6:$S$61,Проходы!$A$6:$A$61,$A3,Проходы!$F$6:$F$61,$B3,Проходы!$G$6:$G$61,$C3,Проходы!$E$6:$E$61,"рабочий") -> 17.305814 | I3: =SQRT(SUMPRODUCT((Проходы!$A$6:$A$61=$A3)*(Проходы!$F$6:$F$61=$B3)*(Проходы!$G$6:$G$61=$C3)*(Проходы!$E$6:$E$61="рабочий")*(Проходы!$S$6:$S$61-H3)^2)/(D3-1)) -> 0.38283058 | J3: =TINV(0.05,D3-1)*I3/SQRT(D3) -> 0.95100388 | K3: =IFERROR(AVERAGEIFS(Проходы!$T$6:$T$61,Проходы!$A$6:$A$61,$A3,Проходы!$F$6:$F$61,$B3,Проходы!$G$6:$G$61,$C3,Проходы!$E$6:$E$61,"рабочий"),"–") -> 0.062676065 | L3: =AVERAGEIFS(Проходы!$R$6:$R$61,Проходы!$A$6:$A$61,$A3,Проходы!$F$6:$F$61,$B3,Проходы!$G$6:$G$61,$C3,Проходы!$E$6:$E$61,"рабочий") -> 0.54211697
A4: культиватор | B4: 0.08 | C4: 5.4 | D4: =COUNTIFS(Проходы!$A$6:$A$61,$A4,Проходы!$F$6:$F$61,$B4,Проходы!$G$6:$G$61,$C4,Проходы!$E$6:$E$61,"рабочий") -> 3 | E4: =AVERAGEIFS(Проходы!$J$6:$J$61,Проходы!$A$6:$A$61,$A4,Проходы!$F$6:$F$61,$B4,Проходы!$G$6:$G$61,$C4,Проходы!$E$6:$E$61,"рабочий") -> 11.732533 | F4: =SQRT(SUMPRODUCT((Проходы!$A$6:$A$61=$A4)*(Проходы!$F$6:$F$61=$B4)*(Проходы!$G$6:$G$61=$C4)*(Проходы!$E$6:$E$61="рабочий")*(Проходы!$J$6:$J$61-E4)^2)/(D4-1)) -> 0.27634407 | G4: =TINV(0.05,D4-1)*F4/SQRT(D4) -> 0.68647672 | H4: =AVERAGEIFS(Проходы!$S$6:$S$61,Проходы!$A$6:$A$61,$A4,Проходы!$F$6:$F$61,$B4,Проходы!$G$6:$G$61,$C4,Проходы!$E$6:$E$61,"рабочий") -> 18.013256 | I4: =SQRT(SUMPRODUCT((Проходы!$A$6:$A$61=$A4)*(Проходы!$F$6:$F$61=$B4)*(Проходы!$G$6:$G$61=$C4)*(Проходы!$E$6:$E$61="рабочий")*(Проходы!$S$6:$S$61-H4)^2)/(D4-1)) -> 0.55814152 | J4: =TINV(0.05,D4-1)*I4/SQRT(D4) -> 1.3865004 | K4: =IFERROR(AVERAGEIFS(Проходы!$T$6:$T$61,Проходы!$A$6:$A$61,$A4,Проходы!$F$6:$F$61,$B4,Проходы!$G$6:$G$61,$C4,Проходы!$E$6:$E$61,"рабочий"),"–") -> 0.060036198 | L4: =AVERAGEIFS(Проходы!$R$6:$R$61,Проходы!$A$6:$A$61,$A4,Проходы!$F$6:$F$61,$B4,Проходы!$G$6:$G$61,$C4,Проходы!$E$6:$E$61,"рабочий") -> 0.65142663
A5: культиватор | B5: 0.11 | C5: 3.6 | D5: =COUNTIFS(Проходы!$A$6:$A$61,$A5,Проходы!$F$6:$F$61,$B5,Проходы!$G$6:$G$61,$C5,Проходы!$E$6:$E$61,"рабочий") -> 3 | E5: =AVERAGEIFS(Проходы!$J$6:$J$61,Проходы!$A$6:$A$61,$A5,Проходы!$F$6:$F$61,$B5,Проходы!$G$6:$G$61,$C5,Проходы!$E$6:$E$61,"рабочий") -> 9.8331333 | F5: =SQRT(SUMPRODUCT((Проходы!$A$6:$A$61=$A5)*(Проходы!$F$6:$F$61=$B5)*(Проходы!$G$6:$G$61=$C5)*(Проходы!$E$6:$E$61="рабочий")*(Проходы!$J$6:$J$61-E5)^2)/(D5-1)) -> 0.2602061 | G5: =TINV(0.05,D5-1)*F5/SQRT(D5) -> 0.64638778 | H5: =AVERAGEIFS(Проходы!$S$6:$S$61,Проходы!$A$6:$A$61,$A5,Проходы!$F$6:$F$61,$B5,Проходы!$G$6:$G$61,$C5,Проходы!$E$6:$E$61,"рабочий") -> 22.822871 | I5: =SQRT(SUMPRODUCT((Проходы!$A$6:$A$61=$A5)*(Проходы!$F$6:$F$61=$B5)*(Проходы!$G$6:$G$61=$C5)*(Проходы!$E$6:$E$61="рабочий")*(Проходы!$S$6:$S$61-H5)^2)/(D5-1)) -> 0.64793217 | J5: =TINV(0.05,D5-1)*I5/SQRT(D5) -> 1.6095527 | K5: =IFERROR(AVERAGEIFS(Проходы!$T$6:$T$61,Проходы!$A$6:$A$61,$A5,Проходы!$F$6:$F$61,$B5,Проходы!$G$6:$G$61,$C5,Проходы!$E$6:$E$61,"рабочий"),"–") -> 0.095196294 | L5: =AVERAGEIFS(Проходы!$R$6:$R$61,Проходы!$A$6:$A$61,$A5,Проходы!$F$6:$F$61,$B5,Проходы!$G$6:$G$61,$C5,Проходы!$E$6:$E$61,"рабочий") -> 0.43086237
A6: культиватор | B6: 0.11 | C6: 4.5 | D6: =COUNTIFS(Проходы!$A$6:$A$61,$A6,Проходы!$F$6:$F$61,$B6,Проходы!$G$6:$G$61,$C6,Проходы!$E$6:$E$61,"рабочий") -> 3 | E6: =AVERAGEIFS(Проходы!$J$6:$J$61,Проходы!$A$6:$A$61,$A6,Проходы!$F$6:$F$61,$B6,Проходы!$G$6:$G$61,$C6,Проходы!$E$6:$E$61,"рабочий") -> 12.0427 | F6: =SQRT(SUMPRODUCT((Проходы!$A$6:$A$61=$A6)*(Проходы!$F$6:$F$61=$B6)*(Проходы!$G$6:$G$61=$C6)*(Проходы!$E$6:$E$61="рабочий")*(Проходы!$J$6:$J$61-E6)^2)/(D6-1)) -> 0.043372918 | G6: =TINV(0.05,D6-1)*F6/SQRT(D6) -> 0.1077443 | H6: =AVERAGEIFS(Проходы!$S$6:$S$61,Проходы!$A$6:$A$61,$A6,Проходы!$F$6:$F$61,$B6,Проходы!$G$6:$G$61,$C6,Проходы!$E$6:$E$61,"рабочий") -> 22.354677 | I6: =SQRT(SUMPRODUCT((Проходы!$A$6:$A$61=$A6)*(Проходы!$F$6:$F$61=$B6)*(Проходы!$G$6:$G$61=$C6)*(Проходы!$E$6:$E$61="рабочий")*(Проходы!$S$6:$S$61-H6)^2)/(D6-1)) -> 0.11939176 | J6: =TINV(0.05,D6-1)*I6/SQRT(D6) -> 0.29658558 | K6: =IFERROR(AVERAGEIFS(Проходы!$T$6:$T$61,Проходы!$A$6:$A$61,$A6,Проходы!$F$6:$F$61,$B6,Проходы!$G$6:$G$61,$C6,Проходы!$E$6:$E$61,"рабочий"),"–") -> 0.087651443 | L6: =AVERAGEIFS(Проходы!$R$6:$R$61,Проходы!$A$6:$A$61,$A6,Проходы!$F$6:$F$61,$B6,Проходы!$G$6:$G$61,$C6,Проходы!$E$6:$E$61,"рабочий") -> 0.53871863
A7: культиватор | B7: 0.11 | C7: 5.4 | D7: =COUNTIFS(Проходы!$A$6:$A$61,$A7,Проходы!$F$6:$F$61,$B7,Проходы!$G$6:$G$61,$C7,Проходы!$E$6:$E$61,"рабочий") -> 3 | E7: =AVERAGEIFS(Проходы!$J$6:$J$61,Проходы!$A$6:$A$61,$A7,Проходы!$F$6:$F$61,$B7,Проходы!$G$6:$G$61,$C7,Проходы!$E$6:$E$61,"рабочий") -> 15.426467 | F7: =SQRT(SUMPRODUCT((Проходы!$A$6:$A$61=$A7)*(Проходы!$F$6:$F$61=$B7)*(Проходы!$G$6:$G$61=$C7)*(Проходы!$E$6:$E$61="рабочий")*(Проходы!$J$6:$J$61-E7)^2)/(D7-1)) -> 0.1530893 | G7: =TINV(0.05,D7-1)*F7/SQRT(D7) -> 0.3802949 | H7: =AVERAGEIFS(Проходы!$S$6:$S$61,Проходы!$A$6:$A$61,$A7,Проходы!$F$6:$F$61,$B7,Проходы!$G$6:$G$61,$C7,Проходы!$E$6:$E$61,"рабочий") -> 23.846566 | I7: =SQRT(SUMPRODUCT((Проходы!$A$6:$A$61=$A7)*(Проходы!$F$6:$F$61=$B7)*(Проходы!$G$6:$G$61=$C7)*(Проходы!$E$6:$E$61="рабочий")*(Проходы!$S$6:$S$61-H7)^2)/(D7-1)) -> 0.45081682 | J7: =TINV(0.05,D7-1)*I7/SQRT(D7) -> 1.1198911 | K7: =IFERROR(AVERAGEIFS(Проходы!$T$6:$T$61,Проходы!$A$6:$A$61,$A7,Проходы!$F$6:$F$61,$B7,Проходы!$G$6:$G$61,$C7,Проходы!$E$6:$E$61,"рабочий"),"–") -> 0.10290011 | L7: =AVERAGEIFS(Проходы!$R$6:$R$61,Проходы!$A$6:$A$61,$A7,Проходы!$F$6:$F$61,$B7,Проходы!$G$6:$G$61,$C7,Проходы!$E$6:$E$61,"рабочий") -> 0.646982
A8: культиватор | B8: 0.14 | C8: 3.6 | D8: =COUNTIFS(Проходы!$A$6:$A$61,$A8,Проходы!$F$6:$F$61,$B8,Проходы!$G$6:$G$61,$C8,Проходы!$E$6:$E$61,"рабочий") -> 3 | E8: =AVERAGEIFS(Проходы!$J$6:$J$61,Проходы!$A$6:$A$61,$A8,Проходы!$F$6:$F$61,$B8,Проходы!$G$6:$G$61,$C8,Проходы!$E$6:$E$61,"рабочий") -> 12.0999 | F8: =SQRT(SUMPRODUCT((Проходы!$A$6:$A$61=$A8)*(Проходы!$F$6:$F$61=$B8)*(Проходы!$G$6:$G$61=$C8)*(Проходы!$E$6:$E$61="рабочий")*(Проходы!$J$6:$J$61-E8)^2)/(D8-1)) -> 0.14945304 | G8: =TINV(0.05,D8-1)*F8/SQRT(D8) -> 0.37126192 | H8: =AVERAGEIFS(Проходы!$S$6:$S$61,Проходы!$A$6:$A$61,$A8,Проходы!$F$6:$F$61,$B8,Проходы!$G$6:$G$61,$C8,Проходы!$E$6:$E$61,"рабочий") -> 28.103137 | I8: =SQRT(SUMPRODUCT((Проходы!$A$6:$A$61=$A8)*(Проходы!$F$6:$F$61=$B8)*(Проходы!$G$6:$G$61=$C8)*(Проходы!$E$6:$E$61="рабочий")*(Проходы!$S$6:$S$61-H8)^2)/(D8-1)) -> 0.28785801 | J8: =TINV(0.05,D8-1)*I8/SQRT(D8) -> 0.71507893 | K8: =IFERROR(AVERAGEIFS(Проходы!$T$6:$T$61,Проходы!$A$6:$A$61,$A8,Проходы!$F$6:$F$61,$B8,Проходы!$G$6:$G$61,$C8,Проходы!$E$6:$E$61,"рабочий"),"–") -> 0.13243943 | L8: =AVERAGEIFS(Проходы!$R$6:$R$61,Проходы!$A$6:$A$61,$A8,Проходы!$F$6:$F$61,$B8,Проходы!$G$6:$G$61,$C8,Проходы!$E$6:$E$61,"рабочий") -> 0.43056667
A9: культиватор | B9: 0.14 | C9: 4.5 | D9: =COUNTIFS(Проходы!$A$6:$A$61,$A9,Проходы!$F$6:$F$61,$B9,Проходы!$G$6:$G$61,$C9,Проходы!$E$6:$E$61,"рабочий") -> 3 | E9: =AVERAGEIFS(Проходы!$J$6:$J$61,Проходы!$A$6:$A$61,$A9,Проходы!$F$6:$F$61,$B9,Проходы!$G$6:$G$61,$C9,Проходы!$E$6:$E$61,"рабочий") -> 15.5144 | F9: =SQRT(SUMPRODUCT((Проходы!$A$6:$A$61=$A9)*(Проходы!$F$6:$F$61=$B9)*(Проходы!$G$6:$G$61=$C9)*(Проходы!$E$6:$E$61="рабочий")*(Проходы!$J$6:$J$61-E9)^2)/(D9-1)) -> 0.54814269 | G9: =TINV(0.05,D9-1)*F9/SQRT(D9) -> 1.3616619 | H9: =AVERAGEIFS(Проходы!$S$6:$S$61,Проходы!$A$6:$A$61,$A9,Проходы!$F$6:$F$61,$B9,Проходы!$G$6:$G$61,$C9,Проходы!$E$6:$E$61,"рабочий") -> 29.047224 | I9: =SQRT(SUMPRODUCT((Проходы!$A$6:$A$61=$A9)*(Проходы!$F$6:$F$61=$B9)*(Проходы!$G$6:$G$61=$C9)*(Проходы!$E$6:$E$61="рабочий")*(Проходы!$S$6:$S$61-H9)^2)/(D9-1)) -> 1.4389659 | J9: =TINV(0.05,D9-1)*I9/SQRT(D9) -> 3.5745894 | K9: =IFERROR(AVERAGEIFS(Проходы!$T$6:$T$61,Проходы!$A$6:$A$61,$A9,Проходы!$F$6:$F$61,$B9,Проходы!$G$6:$G$61,$C9,Проходы!$E$6:$E$61,"рабочий"),"–") -> 0.13719373 | L9: =AVERAGEIFS(Проходы!$R$6:$R$61,Проходы!$A$6:$A$61,$A9,Проходы!$F$6:$F$61,$B9,Проходы!$G$6:$G$61,$C9,Проходы!$E$6:$E$61,"рабочий") -> 0.53436867
A10: фреза | B10: 0.08 | C10: 1.8 | D10: =COUNTIFS(Проходы!$A$6:$A$61,$A10,Проходы!$F$6:$F$61,$B10,Проходы!$G$6:$G$61,$C10,Проходы!$E$6:$E$61,"рабочий") -> 3 | E10: =AVERAGEIFS(Проходы!$J$6:$J$61,Проходы!$A$6:$A$61,$A10,Проходы!$F$6:$F$61,$B10,Проходы!$G$6:$G$61,$C10,Проходы!$E$6:$E$61,"рабочий") -> 7.3030333 | F10: =SQRT(SUMPRODUCT((Проходы!$A$6:$A$61=$A10)*(Проходы!$F$6:$F$61=$B10)*(Проходы!$G$6:$G$61=$C10)*(Проходы!$E$6:$E$61="рабочий")*(Проходы!$J$6:$J$61-E10)^2)/(D10-1)) -> 0.13346656 | G10: =TINV(0.05,D10-1)*F10/SQRT(D10) -> 0.33154932 | H10: =AVERAGEIFS(Проходы!$S$6:$S$61,Проходы!$A$6:$A$61,$A10,Проходы!$F$6:$F$61,$B10,Проходы!$G$6:$G$61,$C10,Проходы!$E$6:$E$61,"рабочий") -> 32.779661 | I10: =SQRT(SUMPRODUCT((Проходы!$A$6:$A$61=$A10)*(Проходы!$F$6:$F$61=$B10)*(Проходы!$G$6:$G$61=$C10)*(Проходы!$E$6:$E$61="рабочий")*(Проходы!$S$6:$S$61-H10)^2)/(D10-1)) -> 1.1311186 | J10: =TINV(0.05,D10-1)*I10/SQRT(D10) -> 2.8098544 | K10: =IFERROR(AVERAGEIFS(Проходы!$T$6:$T$61,Проходы!$A$6:$A$61,$A10,Проходы!$F$6:$F$61,$B10,Проходы!$G$6:$G$61,$C10,Проходы!$E$6:$E$61,"рабочий"),"–") -> – | L10: =AVERAGEIFS(Проходы!$R$6:$R$61,Проходы!$A$6:$A$61,$A10,Проходы!$F$6:$F$61,$B10,Проходы!$G$6:$G$61,$C10,Проходы!$E$6:$E$61,"рабочий") -> 0.222885
A11: фреза | B11: 0.08 | C11: 2.7 | D11: =COUNTIFS(Проходы!$A$6:$A$61,$A11,Проходы!$F$6:$F$61,$B11,Проходы!$G$6:$G$61,$C11,Проходы!$E$6:$E$61,"рабочий") -> 3 | E11: =AVERAGEIFS(Проходы!$J$6:$J$61,Проходы!$A$6:$A$61,$A11,Проходы!$F$6:$F$61,$B11,Проходы!$G$6:$G$61,$C11,Проходы!$E$6:$E$61,"рабочий") -> 9.7834333 | F11: =SQRT(SUMPRODUCT((Проходы!$A$6:$A$61=$A11)*(Проходы!$F$6:$F$61=$B11)*(Проходы!$G$6:$G$61=$C11)*(Проходы!$E$6:$E$61="рабочий")*(Проходы!$J$6:$J$61-E11)^2)/(D11-1)) -> 0.20759061 | G11: =TINV(0.05,D11-1)*F11/SQRT(D11) -> 0.51568367 | H11: =AVERAGEIFS(Проходы!$S$6:$S$61,Проходы!$A$6:$A$61,$A11,Проходы!$F$6:$F$61,$B11,Проходы!$G$6:$G$61,$C11,Проходы!$E$6:$E$61,"рабочий") -> 29.151814 | I11: =SQRT(SUMPRODUCT((Проходы!$A$6:$A$61=$A11)*(Проходы!$F$6:$F$61=$B11)*(Проходы!$G$6:$G$61=$C11)*(Проходы!$E$6:$E$61="рабочий")*(Проходы!$S$6:$S$61-H11)^2)/(D11-1)) -> 0.48027074 | J11: =TINV(0.05,D11-1)*I11/SQRT(D11) -> 1.1930586 | K11: =IFERROR(AVERAGEIFS(Проходы!$T$6:$T$61,Проходы!$A$6:$A$61,$A11,Проходы!$F$6:$F$61,$B11,Проходы!$G$6:$G$61,$C11,Проходы!$E$6:$E$61,"рабочий"),"–") -> 0.0041012486 | L11: =AVERAGEIFS(Проходы!$R$6:$R$61,Проходы!$A$6:$A$61,$A11,Проходы!$F$6:$F$61,$B11,Проходы!$G$6:$G$61,$C11,Проходы!$E$6:$E$61,"рабочий") -> 0.33558587
A12: фреза | B12: 0.08 | C12: 3.6 | D12: =COUNTIFS(Проходы!$A$6:$A$61,$A12,Проходы!$F$6:$F$61,$B12,Проходы!$G$6:$G$61,$C12,Проходы!$E$6:$E$61,"рабочий") -> 3 | E12: =AVERAGEIFS(Проходы!$J$6:$J$61,Проходы!$A$6:$A$61,$A12,Проходы!$F$6:$F$61,$B12,Проходы!$G$6:$G$61,$C12,Проходы!$E$6:$E$61,"рабочий") -> 11.939833 | F12: =SQRT(SUMPRODUCT((Проходы!$A$6:$A$61=$A12)*(Проходы!$F$6:$F$61=$B12)*(Проходы!$G$6:$G$61=$C12)*(Проходы!$E$6:$E$61="рабочий")*(Проходы!$J$6:$J$61-E12)^2)/(D12-1)) -> 0.22982738 | G12: =TINV(0.05,D12-1)*F12/SQRT(D12) -> 0.57092286 | H12: =AVERAGEIFS(Проходы!$S$6:$S$61,Проходы!$A$6:$A$61,$A12,Проходы!$F$6:$F$61,$B12,Проходы!$G$6:$G$61,$C12,Проходы!$E$6:$E$61,"рабочий") -> 26.720254 | I12: =SQRT(SUMPRODUCT((Проходы!$A$6:$A$61=$A12)*(Проходы!$F$6:$F$61=$B12)*(Проходы!$G$6:$G$61=$C12)*(Проходы!$E$6:$E$61="рабочий")*(Проходы!$S$6:$S$61-H12)^2)/(D12-1)) -> 0.47527698 | J12: =TINV(0.05,D12-1)*I12/SQRT(D12) -> 1.1806535 | K12: =IFERROR(AVERAGEIFS(Проходы!$T$6:$T$61,Проходы!$A$6:$A$61,$A12,Проходы!$F$6:$F$61,$B12,Проходы!$G$6:$G$61,$C12,Проходы!$E$6:$E$61,"рабочий"),"–") -> – | L12: =AVERAGEIFS(Проходы!$R$6:$R$61,Проходы!$A$6:$A$61,$A12,Проходы!$F$6:$F$61,$B12,Проходы!$G$6:$G$61,$C12,Проходы!$E$6:$E$61,"рабочий") -> 0.44684063
A13: фреза | B13: 0.12 | C13: 1.8 | D13: =COUNTIFS(Проходы!$A$6:$A$61,$A13,Проходы!$F$6:$F$61,$B13,Проходы!$G$6:$G$61,$C13,Проходы!$E$6:$E$61,"рабочий") -> 3 | E13: =AVERAGEIFS(Проходы!$J$6:$J$61,Проходы!$A$6:$A$61,$A13,Проходы!$F$6:$F$61,$B13,Проходы!$G$6:$G$61,$C13,Проходы!$E$6:$E$61,"рабочий") -> 9.9337667 | F13: =SQRT(SUMPRODUCT((Проходы!$A$6:$A$61=$A13)*(Проходы!$F$6:$F$61=$B13)*(Проходы!$G$6:$G$61=$C13)*(Проходы!$E$6:$E$61="рабочий")*(Проходы!$J$6:$J$61-E13)^2)/(D13-1)) -> 0.048276323 | G13: =TINV(0.05,D13-1)*F13/SQRT(D13) -> 0.11992503 | H13: =AVERAGEIFS(Проходы!$S$6:$S$61,Проходы!$A$6:$A$61,$A13,Проходы!$F$6:$F$61,$B13,Проходы!$G$6:$G$61,$C13,Проходы!$E$6:$E$61,"рабочий") -> 44.381234 | I13: =SQRT(SUMPRODUCT((Проходы!$A$6:$A$61=$A13)*(Проходы!$F$6:$F$61=$B13)*(Проходы!$G$6:$G$61=$C13)*(Проходы!$E$6:$E$61="рабочий")*(Проходы!$S$6:$S$61-H13)^2)/(D13-1)) -> 0.40078881 | J13: =TINV(0.05,D13-1)*I13/SQRT(D13) -> 0.9956146 | K13: =IFERROR(AVERAGEIFS(Проходы!$T$6:$T$61,Проходы!$A$6:$A$61,$A13,Проходы!$F$6:$F$61,$B13,Проходы!$G$6:$G$61,$C13,Проходы!$E$6:$E$61,"рабочий"),"–") -> – | L13: =AVERAGEIFS(Проходы!$R$6:$R$61,Проходы!$A$6:$A$61,$A13,Проходы!$F$6:$F$61,$B13,Проходы!$G$6:$G$61,$C13,Проходы!$E$6:$E$61,"рабочий") -> 0.22383387
... A17: фреза | B17: 0.16 | C17: 2.7 | D17: =COUNTIFS(Проходы!$A$6:$A$61,$A17,Проходы!$F$6:$F$61,$B17,Проходы!$G$6:$G$61,$C17,Проходы!$E$6:$E$61,"рабочий") -> 3 | E17: =AVERAGEIFS(Проходы!$J$6:$J$61,Проходы!$A$6:$A$61,$A17,Проходы!$F$6:$F$61,$B17,Проходы!$G$6:$G$61,$C17,Проходы!$E$6:$E$61,"рабочий") -> 16.266967 | F17: =SQRT(SUMPRODUCT((Проходы!$A$6:$A$61=$A17)*(Проходы!$F$6:$F$61=$B17)*(Проходы!$G$6:$G$61=$C17)*(Проходы!$E$6:$E$61="рабочий")*(Проходы!$J$6:$J$61-E17)^2)/(D17-1)) -> 0.068525129 | G17: =TINV(0.05,D17-1)*F17/SQRT(D17) -> 0.17022586 | H17: =AVERAGEIFS(Проходы!$S$6:$S$61,Проходы!$A$6:$A$61,$A17,Проходы!$F$6:$F$61,$B17,Проходы!$G$6:$G$61,$C17,Проходы!$E$6:$E$61,"рабочий") -> 48.361859 | I17: =SQRT(SUMPRODUCT((Проходы!$A$6:$A$61=$A17)*(Проходы!$F$6:$F$61=$B17)*(Проходы!$G$6:$G$61=$C17)*(Проходы!$E$6:$E$61="рабочий")*(Проходы!$S$6:$S$61-H17)^2)/(D17-1)) -> 0.42629623 | J17: =TINV(0.05,D17-1)*I17/SQRT(D17) -> 1.0589785 | K17: =IFERROR(AVERAGEIFS(Проходы!$T$6:$T$61,Проходы!$A$6:$A$61,$A17,Проходы!$F$6:$F$61,$B17,Проходы!$G$6:$G$61,$C17,Проходы!$E$6:$E$61,"рабочий"),"–") -> -0.0028157309 | L17: =AVERAGEIFS(Проходы!$R$6:$R$61,Проходы!$A$6:$A$61,$A17,Проходы!$F$6:$F$61,$B17,Проходы!$G$6:$G$61,$C17,Проходы!$E$6:$E$61,"рабочий") -> 0.33638

Sheet Энергетика
A1: Машина | B1: a, м | C1: v, км/ч | D1: B, м | E1: v, м/с | F1: A, кДж/м³ (фреза) | G1: R, Н | H1: φ ЭТ | I1: δ ЭТ | J1: φ Д | K1: δ Д | L1: P_эл ЭТ, кВт | M1: P_вх ЭТ, кВт | N1: P_вх Д, кВт | O1: Запас мощности ЭТ | P1: Запас мощности Д | Q1: Допустим ЭТ | R1: Допустим Д | S1: Длительный ЭТ | T1: Q Д, л/ч | U1: X Д
A2: =Опыт_режимы!A2 -> культиватор | B2: =Опыт_режимы!B2 -> 0.08 | C2: =Опыт_режимы!C2 -> 3.6 | D2: =IF(A2="культиватор",1.2,1.25) -> 1.2 | E2: =C2/3.6 -> 1 | F2: =IF(A2="культиватор","",A_0+A_v*C2+A_a*B2) | G2: =IF(A2="культиватор",D2*B2*(k_0+eps*E2^2),"") -> 3510.5855 | H2: =IF(A2="культиватор",G2/(m_ET*g),"") -> 0.27527527 | I2: =IF(A2="культиватор",-LN(1-H2/phi_max)/k_slip,slip_till) -> 0.060506771 | J2: =IF(A2="культиватор",G2/(m_D*g),"") -> 0.31391039 | K2: =IF(A2="культиватор",-LN(1-J2/phi_max)/k_slip,slip_till) -> 0.071383424 | L2: =IF(A2="культиватор",P_aux+M2/eta_ep,P_aux+c_move*E2+P_rot0+F2*D2*B2*E2) -> 7.5726667 | M2: =IF(A2="культиватор",(G2+f_roll*m_ET*g)*E2/(1-I2)/eta_tr/1000,eta_ep*(L2-P_aux)) -> 6.5055467 | N2: =IF(A2="культиватор",(G2+f_roll*m_D*g)*E2/(1-K2)/eta_tr/1000,eta_ep*(c_move*E2*m_D/m_ET+P_rot0+F2*D2*B2*E2))+P_hyd_idle_D -> 6.4504175 | O2: =1-L2*(1+2*cv_P)/P_el_lim -> 0.53922011 | P2: =1-N2*(1+2*cv_P)/P_pto_nom -> 0.58522725 | Q2: =AND(O2>=0,I2<=slip_max) -> TRUE | R2: =AND(P2>=0,K2<=slip_max) -> TRUE | S2: =AND(Q2,M2<=P_mot_1h) -> TRUE | T2: =k_D*(sfc_a*N2+sfc_b*P_pto_nom) -> 3.0088518 | U2: =N2/P_pto_nom -> 0.38951796
A3: =Опыт_режимы!A3 -> культиватор | B3: =Опыт_режимы!B3 -> 0.08 | C3: =Опыт_режимы!C3 -> 4.5 | D3: =IF(A3="культиватор",1.2,1.25) -> 1.2 | E3: =C3/3.6 -> 1.25 | F3: =IF(A3="культиватор","",A_0+A_v*C3+A_a*B3) | G3: =IF(A3="культиватор",D3*B3*(k_0+eps*E3^2),"") -> 3618.001 | H3: =IF(A3="культиватор",G3/(m_ET*g),"") -> 0.28369803 | I3: =IF(A3="культиватор",-LN(1-H3/phi_max)/k_slip,slip_till) -> 0.062810882 | J3: =IF(A3="культиватор",G3/(m_D*g),"") -> 0.3235153 | K3: =IF(A3="культиватор",-LN(1-J3/phi_max)/k_slip,slip_till) -> 0.074215979 | L3: =IF(A3="культиватор",P_aux+M3/eta_ep,P_aux+c_move*E3+P_rot0+F3*D3*B3*E3) -> 9.6285577 | M3: =IF(A3="культиватор",(G3+f_roll*m_ET*g)*E3/(1-I3)/eta_tr/1000,eta_ep*(L3-P_aux)) -> 8.3147308 | N3: =IF(A3="культиватор",(G3+f_roll*m_D*g)*E3/(1-K3)/eta_tr/1000,eta_ep*(c_move*E3*m_D/m_ET+P_rot0+F3*D3*B3*E3))+P_hyd_idle_D -> 8.2144284 | O3: =1-L3*(1+2*cv_P)/P_el_lim -> 0.41412372 | P3: =1-N3*(1+2*cv_P)/P_pto_nom -> 0.47179836 | Q3: =AND(O3>=0,I3<=slip_max) -> TRUE | R3: =AND(P3>=0,K3<=slip_max) -> TRUE | S3: =AND(Q3,M3<=P_mot_1h) -> TRUE | T3: =k_D*(sfc_a*N3+sfc_b*P_pto_nom) -> 3.3969343 | U3: =N3/P_pto_nom -> 0.49604036
A4: =Опыт_режимы!A4 -> культиватор | B4: =Опыт_режимы!B4 -> 0.08 | C4: =Опыт_режимы!C4 -> 5.4 | D4: =IF(A4="культиватор",1.2,1.25) -> 1.2 | E4: =C4/3.6 -> 1.5 | F4: =IF(A4="культиватор","",A_0+A_v*C4+A_a*B4) | G4: =IF(A4="культиватор",D4*B4*(k_0+eps*E4^2),"") -> 3749.2866 | H4: =IF(A4="культиватор",G4/(m_ET*g),"") -> 0.29399252 | I4: =IF(A4="культиватор",-LN(1-H4/phi_max)/k_slip,slip_till) -> 0.065676538 | J4: =IF(A4="культиватор",G4/(m_D*g),"") -> 0.33525462 | K4: =IF(A4="культиватор",-LN(1-J4/phi_max)/k_slip,slip_till) -> 0.077753142 | L4: =IF(A4="культиватор",P_aux+M4/eta_ep,P_aux+c_move*E4+P_rot0+F4*D4*B4*E4) -> 11.825218 | M4: =IF(A4="культиватор",(G4+f_roll*m_ET*g)*E4/(1-I4)/eta_tr/1000,eta_ep*(L4-P_aux)) -> 10.247792 | N4: =IF(A4="культиватор",(G4+f_roll*m_D*g)*E4/(1-K4)/eta_tr/1000,eta_ep*(c_move*E4*m_D/m_ET+P_rot0+F4*D4*B4*E4))+P_hyd_idle_D -> 10.107079 | O4: =1-L4*(1+2*cv_P)/P_el_lim -> 0.28046183 | P4: =1-N4*(1+2*cv_P)/P_pto_nom -> 0.35009772 | Q4: =AND(O4>=0,I4<=slip_max) -> TRUE | R4: =AND(P4>=0,K4<=slip_max) -> TRUE | S4: =AND(Q4,M4<=P_mot_1h) -> TRUE | T4: =k_D*(sfc_a*N4+sfc_b*P_pto_nom) -> 3.8133174 | U4: =N4/P_pto_nom -> 0.61033087
A5: =Опыт_режимы!A5 -> культиватор | B5: =Опыт_режимы!B5 -> 0.11 | C5: =Опыт_режимы!C5 -> 3.6 | D5: =IF(A5="культиватор",1.2,1.25) -> 1.2 | E5: =C5/3.6 -> 1 | F5: =IF(A5="культиватор","",A_0+A_v*C5+A_a*B5) | G5: =IF(A5="культиватор",D5*B5*(k_0+eps*E5^2),"") -> 4827.055 | H5: =IF(A5="культиватор",G5/(m_ET*g),"") -> 0.37850349 | I5: =IF(A5="культиватор",-LN(1-H5/phi_max)/k_slip,slip_till) -> 0.091565024 | J5: =IF(A5="культиватор",G5/(m_D*g),"") -> 0.43162679 | K5: =IF(A5="культиватор",-LN(1-J5/phi_max)/k_slip,slip_till) -> 0.11050596 | L5: =IF(A5="культиватор",P_aux+M5/eta_ep,P_aux+c_move*E5+P_rot0+F5*D5*B5*E5) -> 9.6967481 | M5: =IF(A5="культиватор",(G5+f_roll*m_ET*g)*E5/(1-I5)/eta_tr/1000,eta_ep*(L5-P_aux)) -> 8.3747383 | N5: =IF(A5="культиватор",(G5+f_roll*m_D*g)*E5/(1-K5)/eta_tr/1000,eta_ep*(c_move*E5*m_D/m_ET+P_rot0+F5*D5*B5*E5))+P_hyd_idle_D -> 8.4093698 | O5: =1-L5*(1+2*cv_P)/P_el_lim -> 0.40997449 | P5: =1-N5*(1+2*cv_P)/P_pto_nom -> 0.4592633 | Q5: =AND(O5>=0,I5<=slip_max) -> TRUE | R5: =AND(P5>=0,K5<=slip_max) -> TRUE | S5: =AND(Q5,M5<=P_mot_1h) -> TRUE | T5: =k_D*(sfc_a*N5+sfc_b*P_pto_nom) -> 3.4398214 | U5: =N5/P_pto_nom -> 0.50781219
A6: =Опыт_режимы!A6 -> культиватор | B6: =Опыт_режимы!B6 -> 0.11 | C6: =Опыт_режимы!C6 -> 4.5 | D6: =IF(A6="культиватор",1.2,1.25) -> 1.2 | E6: =C6/3.6 -> 1.25 | F6: =IF(A6="культиватор","",A_0+A_v*C6+A_a*B6) | G6: =IF(A6="культиватор",D6*B6*(k_0+eps*E6^2),"") -> 4974.7513 | H6: =IF(A6="культиватор",G6/(m_ET*g),"") -> 0.39008479 | I6: =IF(A6="культиватор",-LN(1-H6/phi_max)/k_slip,slip_till) -> 0.095492968 | J6: =IF(A6="культиватор",G6/(m_D*g),"") -> 0.44483353 | K6: =IF(A6="культиватор",-LN(1-J6/phi_max)/k_slip,slip_till) -> 0.11561591 | L6: =IF(A6="культиватор",P_aux+M6/eta_ep,P_aux+c_move*E6+P_rot0+F6*D6*B6*E6) -> 12.391169 | M6: =IF(A6="культиватор",(G6+f_roll*m_ET*g)*E6/(1-I6)/eta_tr/1000,eta_ep*(L6-P_aux)) -> 10.745828 | N6: =IF(A6="культиватор",(G6+f_roll*m_D*g)*E6/(1-K6)/eta_tr/1000,eta_ep*(c_move*E6*m_D/m_ET+P_rot0+F6*D6*B6*E6))+P_hyd_idle_D -> 10.771088 | O6: =1-L6*(1+2*cv_P)/P_el_lim -> 0.246025 | P6: =1-N6*(1+2*cv_P)/P_pto_nom -> 0.30740084 | Q6: =AND(O6>=0,I6<=slip_max) -> TRUE | R6: =AND(P6>=0,K6<=slip_max) -> TRUE | S6: =AND(Q6,M6<=P_mot_1h) -> TRUE | T6: =k_D*(sfc_a*N6+sfc_b*P_pto_nom) -> 3.9593993 | U6: =N6/P_pto_nom -> 0.65042801
A7: =Опыт_режимы!A7 -> культиватор | B7: =Опыт_режимы!B7 -> 0.11 | C7: =Опыт_режимы!C7 -> 5.4 | D7: =IF(A7="культиватор",1.2,1.25) -> 1.2 | E7: =C7/3.6 -> 1.5 | F7: =IF(A7="культиватор","",A_0+A_v*C7+A_a*B7) | G7: =IF(A7="культиватор",D7*B7*(k_0+eps*E7^2),"") -> 5155.269 | H7: =IF(A7="культиватор",G7/(m_ET*g),"") -> 0.40423971 | I7: =IF(A7="культиватор",-LN(1-H7/phi_max)/k_slip,slip_till) -> 0.10043958 | J7: =IF(A7="культиватор",G7/(m_D*g),"") -> 0.46097511 | K7: =IF(A7="культиватор",-LN(1-J7/phi_max)/k_slip,slip_till) -> 0.12211049 | L7: =IF(A7="культиватор",P_aux+M7/eta_ep,P_aux+c_move*E7+P_rot0+F7*D7*B7*E7) -> 15.302681 | M7: =IF(A7="культиватор",(G7+f_roll*m_ET*g)*E7/(1-I7)/eta_tr/1000,eta_ep*(L7-P_aux)) -> 13.307959 | N7: =IF(A7="культиватор",(G7+f_roll*m_D*g)*E7/(1-K7)/eta_tr/1000,eta_ep*(c_move*E7*m_D/m_ET+P_rot0+F7*D7*B7*E7))+P_hyd_idle_D -> 13.340095 | O7: =1-L7*(1+2*cv_P)/P_el_lim -> 0.068865962 | P7: =1-N7*(1+2*cv_P)/P_pto_nom -> 0.14220933 | Q7: =AND(O7>=0,I7<=slip_max) -> TRUE | R7: =AND(P7>=0,K7<=slip_max) -> TRUE | S7: =AND(Q7,M7<=P_mot_1h) -> FALSE | T7: =k_D*(sfc_a*N7+sfc_b*P_pto_nom) -> 4.5245809 | U7: =N7/P_pto_nom -> 0.8055613
A8: =Опыт_режимы!A8 -> культиватор | B8: =Опыт_режимы!B8 -> 0.14 | C8: =Опыт_режимы!C8 -> 3.6 | D8: =IF(A8="культиватор",1.2,1.25) -> 1.2 | E8: =C8/3.6 -> 1 | F8: =IF(A8="культиватор","",A_0+A_v*C8+A_a*B8) | G8: =IF(A8="культиватор",D8*B8*(k_0+eps*E8^2),"") -> 6143.5245 | H8: =IF(A8="культиватор",G8/(m_ET*g),"") -> 0.48173171 | I8: =IF(A8="культиватор",-LN(1-H8/phi_max)/k_slip,slip_till) -> 0.13090327 | J8: =IF(A8="культиватор",G8/(m_D*g),"") -> 0.54934318 | K8: =IF(A8="культиватор",-LN(1-J8/phi_max)/k_slip,slip_till) -> 0.16380656 | L8: =IF(A8="культиватор",P_aux+M8/eta_ep,P_aux+c_move*E8+P_rot0+F8*D8*B8*E8) -> 12.083546 | M8: =IF(A8="культиватор",(G8+f_roll*m_ET*g)*E8/(1-I8)/eta_tr/1000,eta_ep*(L8-P_aux)) -> 10.475121 | N8: =IF(A8="культиватор",(G8+f_roll*m_D*g)*E8/(1-K8)/eta_tr/1000,eta_ep*(c_move*E8*m_D/m_ET+P_rot0+F8*D8*B8*E8))+P_hyd_idle_D -> 10.724884 | O8: =1-L8*(1+2*cv_P)/P_el_lim -> 0.26474313 | P8: =1-N8*(1+2*cv_P)/P_pto_nom -> 0.31037184 | Q8: =AND(O8>=0,I8<=slip_max) -> TRUE | R8: =AND(P8>=0,K8<=slip_max) -> FALSE | S8: =AND(Q8,M8<=P_mot_1h) -> TRUE | T8: =k_D*(sfc_a*N8+sfc_b*P_pto_nom) -> 3.9492344 | U8: =N8/P_pto_nom -> 0.6476379
A9: =Опыт_режимы!A9 -> культиватор | B9: =Опыт_режимы!B9 -> 0.14 | C9: =Опыт_режимы!C9 -> 4.5 | D9: =IF(A9="культиватор",1.2,1.25) -> 1.2 | E9: =C9/3.6 -> 1.25 | F9: =IF(A9="культиватор","",A_0+A_v*C9+A_a*B9) | G9: =IF(A9="культиватор",D9*B9*(k_0+eps*E9^2),"") -> 6331.5017 | H9: =IF(A9="культиватор",G9/(m_ET*g),"") -> 0.49647155 | I9: =IF(A9="культиватор",-LN(1-H9/phi_max)/k_slip,slip_till) -> 0.1374799 | J9: =IF(A9="культиватор",G9/(m_D*g),"") -> 0.56615177 | K9: =IF(A9="культиватор",-LN(1-J9/phi_max)/k_slip,slip_till) -> 0.1732605 | L9: =IF(A9="культиватор",P_aux+M9/eta_ep,P_aux+c_move*E9+P_rot0+F9*D9*B9*E9) -> 15.524675 | M9: =IF(A9="культиватор",(G9+f_roll*m_ET*g)*E9/(1-I9)/eta_tr/1000,eta_ep*(L9-P_aux)) -> 13.503314 | N9: =IF(A9="культиватор",(G9+f_roll*m_D*g)*E9/(1-K9)/eta_tr/1000,eta_ep*(c_move*E9*m_D/m_ET+P_rot0+F9*D9*B9*E9))+P_hyd_idle_D -> 13.842733 | O9: =1-L9*(1+2*cv_P)/P_el_lim -> 0.055358134 | P9: =1-N9*(1+2*cv_P)/P_pto_nom -> 0.10988885 | Q9: =AND(O9>=0,I9<=slip_max) -> TRUE | R9: =AND(P9>=0,K9<=slip_max) -> FALSE | S9: =AND(Q9,M9<=P_mot_1h) -> FALSE | T9: =k_D*(sfc_a*N9+sfc_b*P_pto_nom) -> 4.6351613 | U9: =N9/P_pto_nom -> 0.83591384
A10: =Опыт_режимы!A10 -> фреза | B10: =Опыт_режимы!B10 -> 0.08 | C10: =Опыт_режимы!C10 -> 1.8 | D10: =IF(A10="культиватор",1.2,1.25) -> 1.25 | E10: =C10/3.6 -> 0.5 | F10: =IF(A10="культиватор","",A_0+A_v*C10+A_a*B10) -> 104.79984 | G10: =IF(A10="культиватор",D10*B10*(k_0+eps*E10^2),"") | H10: =IF(A10="культиватор",G10/(m_ET*g),"") | I10: =IF(A10="культиватор",-LN(1-H10/phi_max)/k_slip,slip_till) -> 0 | J10: =IF(A10="культиватор",G10/(m_D*g),"") | K10: =IF(A10="культиватор",-LN(1-J10/phi_max)/k_slip,slip_till) -> 0 | L10: =IF(A10="культиватор",P_aux+M10/eta_ep,P_aux+c_move*E10+P_rot0+F10*D10*B10*E10) -> 7.4305709 | M10: =IF(A10="культиватор",(G10+f_roll*m_ET*g)*E10/(1-I10)/eta_tr/1000,eta_ep*(L10-P_aux)) -> 6.3805024 | N10: =IF(A10="культиватор",(G10+f_roll*m_D*g)*E10/(1-K10)/eta_tr/1000,eta_ep*(c_move*E10*m_D/m_ET+P_rot0+F10*D10*B10*E10))+P_hyd_idle_D -> 6.4190127 | O10: =1-L10*(1+2*cv_P)/P_el_lim -> 0.54786632 | P10: =1-N10*(1+2*cv_P)/P_pto_nom -> 0.58724663 | Q10: =AND(O10>=0,I10<=slip_max) -> TRUE | R10: =AND(P10>=0,K10<=slip_max) -> TRUE | S10: =AND(Q10,M10<=P_mot_1h) -> TRUE | T10: =k_D*(sfc_a*N10+sfc_b*P_pto_nom) -> 3.0019428 | U10: =N10/P_pto_nom -> 0.38762154
A11: =Опыт_режимы!A11 -> фреза | B11: =Опыт_режимы!B11 -> 0.08 | C11: =Опыт_режимы!C11 -> 2.7 | D11: =IF(A11="культиватор",1.2,1.25) -> 1.25 | E11: =C11/3.6 -> 0.75 | F11: =IF(A11="культиватор","",A_0+A_v*C11+A_a*B11) -> 95.553462 | G11: =IF(A11="культиватор",D11*B11*(k_0+eps*E11^2),"") | H11: =IF(A11="культиватор",G11/(m_ET*g),"") | I11: =IF(A11="культиватор",-LN(1-H11/phi_max)/k_slip,slip_till) -> 0 | J11: =IF(A11="культиватор",G11/(m_D*g),"") | K11: =IF(A11="культиватор",-LN(1-J11/phi_max)/k_slip,slip_till) -> 0 | L11: =IF(A11="культиватор",P_aux+M11/eta_ep,P_aux+c_move*E11+P_rot0+F11*D11*B11*E11) -> 9.871778 | M11: =IF(A11="культиватор",(G11+f_roll*m_ET*g)*E11/(1-I11)/eta_tr/1000,eta_ep*(L11-P_aux)) -> 8.5287647 | N11: =IF(A11="культиватор",(G11+f_roll*m_D*g)*E11/(1-K11)/eta_tr/1000,eta_ep*(c_move*E11*m_D/m_ET+P_rot0+F11*D11*B11*E11))+P_hyd_idle_D -> 8.5115302 | O11: =1-L11*(1+2*cv_P)/P_el_lim -> 0.39932431 | P11: =1-N11*(1+2*cv_P)/P_pto_nom -> 0.45269422 | Q11: =AND(O11>=0,I11<=slip_max) -> TRUE | R11: =AND(P11>=0,K11<=slip_max) -> TRUE | S11: =AND(Q11,M11<=P_mot_1h) -> TRUE | T11: =k_D*(sfc_a*N11+sfc_b*P_pto_nom) -> 3.4622966 | U11: =N11/P_pto_nom -> 0.51398129
A12: =Опыт_режимы!A12 -> фреза | B12: =Опыт_режимы!B12 -> 0.08 | C12: =Опыт_режимы!C12 -> 3.6 | D12: =IF(A12="культиватор",1.2,1.25) -> 1.25 | E12: =C12/3.6 -> 1 | F12: =IF(A12="культиватор","",A_0+A_v*C12+A_a*B12) -> 86.307084 | G12: =IF(A12="культиватор",D12*B12*(k_0+eps*E12^2),"") | H12: =IF(A12="культиватор",G12/(m_ET*g),"") | I12: =IF(A12="культиватор",-LN(1-H12/phi_max)/k_slip,slip_till) -> 0 | J12: =IF(A12="культиватор",G12/(m_D*g),"") | K12: =IF(A12="культиватор",-LN(1-J12/phi_max)/k_slip,slip_till) -> 0 | L12: =IF(A12="культиватор",P_aux+M12/eta_ep,P_aux+c_move*E12+P_rot0+F12*D12*B12*E12) -> 11.850666 | M12: =IF(A12="культиватор",(G12+f_roll*m_ET*g)*E12/(1-I12)/eta_tr/1000,eta_ep*(L12-P_aux)) -> 10.270186 | N12: =IF(A12="культиватор",(G12+f_roll*m_D*g)*E12/(1-K12)/eta_tr/1000,eta_ep*(c_move*E12*m_D/m_ET+P_rot0+F12*D12*B12*E12))+P_hyd_idle_D -> 10.197207 | O12: =1-L12*(1+2*cv_P)/P_el_lim -> 0.27891337 | P12: =1-N12*(1+2*cv_P)/P_pto_nom -> 0.34430235 | Q12: =AND(O12>=0,I12<=slip_max) -> TRUE | R12: =AND(P12>=0,K12<=slip_max) -> TRUE | S12: =AND(Q12,M12<=P_mot_1h) -> TRUE | T12: =k_D*(sfc_a*N12+sfc_b*P_pto_nom) -> 3.8331455 | U12: =N12/P_pto_nom -> 0.61577337
A13: =Опыт_режимы!A13 -> фреза | B13: =Опыт_режимы!B13 -> 0.12 | C13: =Опыт_режимы!C13 -> 1.8 | D13: =IF(A13="культиватор",1.2,1.25) -> 1.25 | E13: =C13/3.6 -> 0.5 | F13: =IF(A13="культиватор","",A_0+A_v*C13+A_a*B13) -> 103.67081 | G13: =IF(A13="культиватор",D13*B13*(k_0+eps*E13^2),"") | H13: =IF(A13="культиватор",G13/(m_ET*g),"") | I13: =IF(A13="культиватор",-LN(1-H13/phi_max)/k_slip,slip_till) -> 0 | J13: =IF(A13="культиватор",G13/(m_D*g),"") | K13: =IF(A13="культиватор",-LN(1-J13/phi_max)/k_slip,slip_till) -> 0 | L13: =IF(A13="культиватор",P_aux+M13/eta_ep,P_aux+c_move*E13+P_rot0+F13*D13*B13*E13) -> 9.9658899 | M13: =IF(A13="культиватор",(G13+f_roll*m_ET*g)*E13/(1-I13)/eta_tr/1000,eta_ep*(L13-P_aux)) -> 8.6115831 | N13: =IF(A13="культиватор",(G13+f_roll*m_D*g)*E13/(1-K13)/eta_tr/1000,eta_ep*(c_move*E13*m_D/m_ET+P_rot0+F13*D13*B13*E13))+P_hyd_idle_D -> 8.6500934 | O13: =1-L13*(1+2*cv_P)/P_el_lim -> 0.39359781 | P13: =1-N13*(1+2*cv_P)/P_pto_nom -> 0.44378437 | Q13: =AND(O13>=0,I13<=slip_max) -> TRUE | R13: =AND(P13>=0,K13<=slip_max) -> TRUE | S13: =AND(Q13,M13<=P_mot_1h) -> TRUE | T13: =k_D*(sfc_a*N13+sfc_b*P_pto_nom) -> 3.4927806 | U13: =N13/P_pto_nom -> 0.52234864
